Workbook

Sheet Financial Summary
A1: XRANGE FLAGSHIP DEVELOPMENT PROFILE | D1: BASELINE SCENARIO | M1: 45135
A3: Project: | B3: Base Case | D3: AED:USD | E3: 3.67
A4: Location: | B4: Dubai
A5: Project Type: | B5: XRange | L5: Revenue Escalation | N5: 0.03
A6: Currency | B6: UAE Dirhams | L6: Cost Escalation | N6: 0.03
U7: 0.25010801
A8: IRR | B8: =IRR(C98:N98,0.1) -> 0.41824331 | E8: SPENDING EXPECTATIONS PER PERSON | Q8: IRR | U8: 1.5673434e+08
A9: NPV @ 10% | B9: =NPV(0.1,C98:N98) -> 87312336 | D9: Bay Only | E9: =E23/$B$11 -> 41.89145 | F9: =F23/$B$11 -> 104.78847 | G9: =G23/$B$11 -> 126.97897 | H9: =H23/$B$11 -> 130.78834 | I9: =I23/$B$11 -> 134.71199 | J9: =J23/$B$11 -> 138.75335 | K9: =K23/$B$11 -> 142.91595 | L9: =L23/$B$11 -> 147.20343 | ... N9: =N23/$B$11 -> 156.16812 | Q9: NPV @ 10%
D10: F&B Spend | E10: =E29/$B$11 -> 41.89145 | F10: =F29/$B$11 -> 104.78847 | G10: =G29/$B$11 -> 126.97897 | H10: =H29/$B$11 -> 130.78834 | I10: =I29/$B$11 -> 134.71199 | J10: =J29/$B$11 -> 138.75335 | K10: =K29/$B$11 -> 142.91595 | L10: =L29/$B$11 -> 147.20343 | ... N10: =N29/$B$11 -> 156.16812 | U10: 324454.87
A11: Estimated Distinct Users Per Annum | B11: =H135 -> 140157.4 | D11: Other | E11: =(E24+E25+E35)/$B$11 -> 16.944531 | F11: =(F24+F25+F35)/$B$11 -> 42.385534 | G11: =(G24+G25+G35)/$B$11 -> 51.361294 | H11: =(H24+H25+H35)/$B$11 -> 52.902133 | I11: =(I24+I25+I35)/$B$11 -> 54.489197 | J11: =(J24+J25+J35)/$B$11 -> 56.123872 | K11: =(K24+K25+K35)/$B$11 -> 57.807589 | L11: =(L24+L25+L35)/$B$11 -> 59.541816 | ... N11: =(N24+N25+N35)/$B$11 -> 63.167913 | Q11: Estimated Distinct Users Per Annum | U11: 200
A12: Average Hourly Rate Per Standard Bay (2023) | B12: =D123/B118 -> 199.61476 | D12: TOTAL | E12: =SUM(E9:E11) -> 100.72743 | F12: =SUM(F9:F11) -> 251.96247 | G12: =SUM(G9:G11) -> 305.31923 | H12: =SUM(H9:H11) -> 314.47881 | I12: =SUM(I9:I11) -> 323.91318 | J12: =SUM(J9:J11) -> 333.63057 | K12: =SUM(K9:K11) -> 343.63949 | L12: =SUM(L9:L11) -> 353.94867 | ... N12: =SUM(N9:N11) -> 375.50415 | Q12: Average Hourly Rate Per Standard Bay (2023)
C14: Days of Operation | E14: =365/2 -> 182.5 | F14: 365 | G14: =F14 -> 365 | H14: =G14 -> 365 | I14: =H14 -> 365 | J14: =I14 -> 365 | K14: =J14 -> 365 | L14: =K14 -> 365 | M14: =L14 -> 365 | N14: =M14 -> 365
C15: Number of Bays | E15: =B126 -> 25 | F15: =E15 -> 25 | G15: =F15 -> 25 | H15: =G15 -> 25 | I15: =H15 -> 25 | J15: =I15 -> 25 | K15: =J15 -> 25 | L15: =K15 -> 25 | M15: =L15 -> 25 | N15: =M15 -> 25
C16: Average Bay Occupancy | E16: =G16*(1+E18) -> 0.38584693 | F16: =G16*(1+F18) -> 0.46852842 | G16: =G126 -> 0.55120991 | H16: =G16 -> 0.55120991 | I16: =H16 -> 0.55120991 | J16: =I16 -> 0.55120991 | K16: =J16 -> 0.55120991 | L16: =K16 -> 0.55120991 | M16: =L16 -> 0.55120991 | N16: =M16 -> 0.55120991
C17: Average Daily Bay Rate | E17: =D126*(1+N5)^3 -> 3335.2124 | F17: =E17*(1+$N$5) -> 3435.2687 | G17: =F17*(1+$N$5) -> 3538.3268 | H17: =G17*(1+$N$5) -> 3644.4766 | I17: =H17*(1+$N$5) -> 3753.8109 | J17: =I17*(1+$N$5) -> 3866.4252 | K17: =J17*(1+$N$5) -> 3982.418 | L17: =K17*(1+$N$5) -> 4101.8905 | M17: =L17*(1+$N$5) -> 4224.9472 | N17: =M17*(1+$N$5) -> 4351.6957
C18: Stabilization | E18: -0.3 | F18: -0.15 | G18: 0 | H18: 0 | I18: 0 | J18: 0 | K18: 0 | L18: 0 | M18: 0 | N18: 0
C20: 2023 | D20: =C20+1 -> 2024 | E20: =D20+1 -> 2025 | F20: =E20+1 -> 2026 | G20: =F20+1 -> 2027 | H20: =G20+1 -> 2028 | I20: =H20+1 -> 2029 | J20: =I20+1 -> 2030 | K20: =J20+1 -> 2031 | ... N20: =M20+1 -> 2034
C21: Year 1 | D21: Year 2 | E21: Year 3 | F21: Year 4 | G21: Year 5 | H21: Year 6 | I21: Year 7 | J21: Year 8 | K21: Year 9 | L21: Year 10 | M21: Year 11 | N21: Year 12
A22: REVENUES
A23: Bay Revenues | E23: =E14*E15*E16*E17 -> 5871396.7 | F23: =F14*F15*F16*F17 -> 14686879 | G23: =G14*G15*G16*G17 -> 17797042 | H23: =H14*H15*H16*H17 -> 18330953 | I23: =I14*I15*I16*I17 -> 18880882 | J23: =J14*J15*J16*J17 -> 19447308 | K23: =K14*K15*K16*K17 -> 20030728 | L23: =L14*L15*L16*L17 -> 20631650 | ... N23: =N14*N15*N16*N17 -> 21888117
A24: Memberships | B24: 0 | C24: of Bay Rev | E24: =$B$24*E23 -> 0 | F24: =$B$24*F23 -> 0 | G24: =$B$24*G23 -> 0 | H24: =$B$24*H23 -> 0 | I24: =$B$24*I23 -> 0 | J24: =$B$24*J23 -> 0 | K24: =$B$24*K23 -> 0 | L24: =$B$24*L23 -> 0 | ... N24: =$B$24*N23 -> 0
A25: XRange Academy Revenues | B25: 0.07 | C25: of Bay Rev | E25: =$B$25*E23 -> 410997.77 | F25: =$B$25*F23 -> 1028081.6 | G25: =$B$25*G23 -> 1245792.9 | H25: =$B$25*H23 -> 1283166.7 | I25: =$B$25*I23 -> 1321661.7 | J25: =$B$25*J23 -> 1361311.6 | K25: =$B$25*K23 -> 1402150.9 | L25: =$B$25*L23 -> 1444215.5 | ... N25: =$B$25*N23 -> 1532168.2
A26: Sub-Total Golf Revenues | E26: =SUM(E23:E25) -> 6282394.5 | F26: =SUM(F23:F25) -> 15714961 | G26: =SUM(G23:G25) -> 19042835 | H26: =SUM(H23:H25) -> 19614120 | I26: =SUM(I23:I25) -> 20202544 | J26: =SUM(J23:J25) -> 20808620 | K26: =SUM(K23:K25) -> 21432879 | L26: =SUM(L23:L25) -> 22075865 | ... N26: =SUM(N23:N25) -> 23420285
A27: XRange Dining | B27: 1 | C27: of Golf Revenue | E27: =$B$27*E23 -> 5871396.7 | F27: =$B$27*F23 -> 14686879 | G27: =$B$27*G23 -> 17797042 | H27: =$B$27*H23 -> 18330953 | I27: =$B$27*I23 -> 18880882 | J27: =$B$27*J23 -> 19447308 | K27: =$B$27*K23 -> 20030728 | L27: =$B$27*L23 -> 20631650 | ... N27: =$B$27*N23 -> 21888117
A28: Food & Beverage - Leased | B28: 0 | C28: Rental (AED psm) | D28: 1575 | E28: =$B28*$D28*(1+E$18)*(1+$N$5)^3*E14/365 -> 0 | F28: =$B28*$D28*(1+F$18)*(1+$N$5)^4 -> 0 | G28: =$B28*$D28*(1+G$18)*(1+$N$5)^5 -> 0 | H28: =$B28*$D28*(1+H$18)*(1+$N$5)^6 -> 0 | I28: =$B28*$D28*(1+I$18)*(1+$N$5)^7 -> 0 | J28: =$B28*$D28*(1+J$18)*(1+$N$5)^8 -> 0 | K28: =$B28*$D28*(1+K$18)*(1+$N$5)^9 -> 0 | L28: =$B28*$D28*(1+L$18)*(1+$N$5)^10 -> 0 | M28: =$B28*$D28*(1+M$18)*(1+$N$5)^11 -> 0 | N28: =$B28*$D28*(1+N$18)*(1+$N$5)^12 -> 0
A29: Food & Beverage | E29: =SUM(E27:E28) -> 5871396.7 | F29: =SUM(F27:F28) -> 14686879 | G29: =SUM(G27:G28) -> 17797042 | H29: =SUM(H27:H28) -> 18330953 | I29: =SUM(I27:I28) -> 18880882 | J29: =SUM(J27:J28) -> 19447308 | K29: =SUM(K27:K28) -> 20030728 | L29: =SUM(L27:L28) -> 20631650 | ... N29: =SUM(N27:N28) -> 21888117
A30: VR Arcade | B30: 0 | C30: =C28 -> Rental (AED psm) | D30: 0 | E30: =$B30*$D30*(1+E$18)*(1+$N$5)^3*E14/365 -> 0 | F30: =$B30*$D30*(1+F$18)*(1+$N$5)^4 -> 0 | G30: =$B30*$D30*(1+G$18)*(1+$N$5)^5 -> 0 | H30: =$B30*$D30*(1+H$18)*(1+$N$5)^6 -> 0 | I30: =$B30*$D30*(1+I$18)*(1+$N$5)^7 -> 0 | J30: =$B30*$D30*(1+J$18)*(1+$N$5)^8 -> 0 | K30: =$B30*$D30*(1+K$18)*(1+$N$5)^9 -> 0 | L30: =$B30*$D30*(1+L$18)*(1+$N$5)^10 -> 0 | M30: =$B30*$D30*(1+M$18)*(1+$N$5)^11 -> 0 | N30: =$B30*$D30*(1+N$18)*(1+$N$5)^12 -> 0
A31: Merchandising Store | B31: 1350 | C31: =C30 -> Rental (AED psm) | D31: 100 | E31: =$B31*$D31*(1+E$18)*(1+$N$5)^3*E14/365 -> 51631.351 | F31: =$B31*$D31*(1+F$18)*(1+$N$5)^4 -> 129152.14 | G31: =$B31*$D31*(1+G$18)*(1+$N$5)^5 -> 156502 | H31: =$B31*$D31*(1+H$18)*(1+$N$5)^6 -> 161197.06 | I31: =$B31*$D31*(1+I$18)*(1+$N$5)^7 -> 166032.97 | J31: =$B31*$D31*(1+J$18)*(1+$N$5)^8 -> 171013.96 | K31: =$B31*$D31*(1+K$18)*(1+$N$5)^9 -> 176144.38 | L31: =$B31*$D31*(1+L$18)*(1+$N$5)^10 -> 181428.71 | M31: =$B31*$D31*(1+M$18)*(1+$N$5)^11 -> 186871.57 | N31: =$B31*$D31*(1+N$18)*(1+$N$5)^12 -> 192477.72
A32: Health Club / Salon | B32: 0 | C32: =C31 -> Rental (AED psm) | D32: 0 | E32: =$B32*$D32*(1+E$18)*(1+$N$5)^3*E14/365 -> 0 | F32: =$B32*$D32*(1+F$18)*(1+$N$5)^4 -> 0 | G32: =$B32*$D32*(1+G$18)*(1+$N$5)^5 -> 0 | H32: =$B32*$D32*(1+H$18)*(1+$N$5)^6 -> 0 | I32: =$B32*$D32*(1+I$18)*(1+$N$5)^7 -> 0 | J32: =$B32*$D32*(1+J$18)*(1+$N$5)^8 -> 0 | K32: =$B32*$D32*(1+K$18)*(1+$N$5)^9 -> 0 | L32: =$B32*$D32*(1+L$18)*(1+$N$5)^10 -> 0 | M32: =$B32*$D32*(1+M$18)*(1+$N$5)^11 -> 0 | N32: =$B32*$D32*(1+N$18)*(1+$N$5)^12 -> 0
A33: Sponsorships & Advertising | B33: 5000000 | C33: Estimate | E33: =$B$33*(1+E$18)*(1+$N$6)^3*E14/365 -> 1912272.2 | F33: =$B$33*(1+F$18)*(1+$N$6)^4 -> 4783412.4 | G33: =$B$33*(1+G$18)*(1+$N$6)^5 -> 5796370.4 | H33: =$B$33*(1+H$18)*(1+$N$6)^6 -> 5970261.5 | I33: =$B$33*(1+I$18)*(1+$N$6)^7 -> 6149369.3 | J33: =$B$33*(1+J$18)*(1+$N$6)^8 -> 6333850.4 | K33: =$B$33*(1+K$18)*(1+$N$6)^9 -> 6523865.9 | L33: =$B$33*(1+L$18)*(1+$N$6)^10 -> 6719581.9 | M33: =$B$33*(1+M$18)*(1+$N$6)^11 -> 6921169.4 | N33: =$B$33*(1+N$18)*(1+$N$6)^12 -> 7128804.4
A34: Misc. Revenues | B34: 0 | C34: of Bay Rev | E34: =$B$34*E23 -> 0 | F34: =$B$34*F23 -> 0 | G34: =$B$34*G23 -> 0 | H34: =$B$34*H23 -> 0 | I34: =$B$34*I23 -> 0 | J34: =$B$34*J23 -> 0 | K34: =$B$34*K23 -> 0 | L34: =$B$34*L23 -> 0 | ... N34: =$B$34*N23 -> 0
A35: Sub-Total Other Revenues | E35: =SUM(E30:E34) -> 1963903.6 | F35: =SUM(F30:F34) -> 4912564.6 | G35: =SUM(G30:G34) -> 5952872.4 | H35: =SUM(H30:H34) -> 6131458.5 | I35: =SUM(I30:I34) -> 6315402.3 | J35: =SUM(J30:J34) -> 6504864.4 | K35: =SUM(K30:K34) -> 6700010.3 | L35: =SUM(L30:L34) -> 6901010.6 | ... N35: =SUM(N30:N34) -> 7321282.2
A36: TOTAL OPERATIONAL REVENUES | E36: =E26+E29+E35 -> 14117695 | F36: =F26+F29+F35 -> 35314405 | G36: =G26+G29+G35 -> 42792750 | H36: =H26+H29+H35 -> 44076532 | I36: =I26+I29+I35 -> 45398828 | J36: =J26+J29+J35 -> 46760793 | K36: =K26+K29+K35 -> 48163617 | L36: =L26+L29+L35 -> 49608525 | ... N36: =N26+N29+N35 -> 52629684 | Q36: TOTAL OPERATIONAL REVENUES | U36: 37059186 | V36: 92700908 | W36: 1.1233169e+08 | X36: 1.1570164e+08 | Y36: 1.1917269e+08 | Z36: 1.2274787e+08 | AA36: 1.264303e+08 | AB36: 1.3022321e+08 | AC36: 1.3412991e+08 | AD36: 1.3815381e+08
A38: DIRECT COSTS
A39: Golf Operations | B39: 0.15 | C39: of Bay / Member Revenue | E39: =$B$39*(E23+E24) -> 880709.5 | F39: =$B$39*(F23+F24) -> 2203031.9 | G39: =$B$39*(G23+G24) -> 2669556.3 | H39: =$B$39*(H23+H24) -> 2749643 | I39: =$B$39*(I23+I24) -> 2832132.3 | J39: =$B$39*(J23+J24) -> 2917096.3 | K39: =$B$39*(K23+K24) -> 3004609.2 | L39: =$B$39*(L23+L24) -> 3094747.4 | ... N39: =$B$39*(N23+N24) -> 3283217.5
A40: XRange Technology Servicing Fee | B40: 255000 | C40: USD Annual Fee Adj. for Inflation | E40: =$B$40*$E$3*(1+$N$6)^3 -> 1022628.6 | F40: =$B$40*$E$3*(1+$N$6)^4 -> 1053307.4 | G40: =$B$40*$E$3*(1+$N$6)^5 -> 1084906.6 | H40: =$B$40*$E$3*(1+$N$6)^6 -> 1117453.8 | I40: =$B$40*$E$3*(1+$N$6)^7 -> 1150977.5 | J40: =$B$40*$E$3*(1+$N$6)^8 -> 1185506.8 | K40: =$B$40*$E$3*(1+$N$6)^9 -> 1221072 | L40: =$B$40*$E$3*(1+$N$6)^10 -> 1257704.1 | M40: =$B$40*$E$3*(1+$N$6)^11 -> 1295435.3 | N40: =$B$40*$E$3*(1+$N$6)^12 -> 1334298.3
A41: XRange Academy | B41: 0.5 | C41: of Academy Revenue | E41: =$B$41*E25 -> 205498.88 | F41: =$B$41*F25 -> 514040.78 | G41: =$B$41*G25 -> 622896.47 | H41: =$B$41*H25 -> 641583.37 | I41: =$B$41*I25 -> 660830.87 | J41: =$B$41*J25 -> 680655.8 | K41: =$B$41*K25 -> 701075.47 | L41: =$B$41*L25 -> 722107.73 | ... N41: =$B$41*N25 -> 766084.09
A42: F&B Operations | B42: 0.65 | C42: of F&B Rev | E42: =$B$42*E29 -> 3816407.8 | F42: =$B$42*F29 -> 9546471.6 | G42: =$B$42*G29 -> 11568077 | H42: =$B$42*H29 -> 11915120 | I42: =$B$42*I29 -> 12272573 | J42: =$B$42*J29 -> 12640750 | K42: =$B$42*K29 -> 13019973 | L42: =$B$42*L29 -> 13410572 | ... N42: =$B$42*N29 -> 14227276
A43: VR Arcade | B43: 0.1 | C43: of VR Arcade | E43: =$B$43*E30 -> 0 | F43: =$B$43*F30 -> 0 | G43: =$B$43*G30 -> 0 | H43: =$B$43*H30 -> 0 | I43: =$B$43*I30 -> 0 | J43: =$B$43*J30 -> 0 | K43: =$B$43*K30 -> 0 | L43: =$B$43*L30 -> 0 | ... N43: =$B$43*N30 -> 0
A44: Merchandising Store | B44: 0.1 | C44: of Merchandising | E44: =$B$44*E31 -> 5163.1351 | F44: =$B$44*F31 -> 12915.214 | G44: =$B$44*G31 -> 15650.2 | H44: =$B$44*H31 -> 16119.706 | I44: =$B$44*I31 -> 16603.297 | J44: =$B$44*J31 -> 17101.396 | K44: =$B$44*K31 -> 17614.438 | L44: =$B$44*L31 -> 18142.871 | ... N44: =$B$44*N31 -> 19247.772
...

Sheet Bay Revenue
A1: XRANGE - BREAKDOWN OF BAY REVENUE BY WEEKDAY/WEEKEND AND PEAK/NON-PEAK | H1: ='Financial Summary'!M1 -> 45135
A3: SUMMARY
A5: BAY REVENUE | B5: # BAYS | C5: % OF STANDARD | D5: DAILY BAY RATE | E5: REV POTENTIAL | G5: REV EFFICIENCY | H5: REVENUE
E6: =B24 -> AED | F6: =C24 -> USD | H6: =B24 -> AED | I6: =C24 -> USD
A7: Mini-Bays | B7: 0 | C7: =D7/D8 -> #DIV/0! | D7: =E7/B7/$C30 -> #DIV/0! | E7: =E64+E86+E110+E132 -> 0 | F7: =F64+F86+F110+F132 -> 0 | G7: =H7/E7 -> #DIV/0! | H7: =H64+H86+H110+H132 -> 0 | I7: =I64+I86+I110+I132 -> 0
A8: Standard Bays | B8: 25 | C8: 1 | D8: =E8/B8/$C30 -> 3052.1918 | E8: =E65+E87+E111+E133 -> 27851250 | F8: =F65+F87+F111+F133 -> 7588896.5 | G8: =H8/E8 -> 0.55120991 | H8: =H65+H87+H111+H133 -> 15351885 | I8: =I65+I87+I111+I133 -> 4183074.9
A9: Premium Bays | B9: 0 | C9: =D9/D8 -> #DIV/0! | D9: =E9/B9/$C30 -> #DIV/0! | E9: =E66+E88+E112+E134 -> 0 | F9: =F66+F88+F112+F134 -> 0 | G9: =H9/E9 -> #DIV/0! | H9: =H66+H88+H112+H134 -> 0 | I9: =I66+I88+I112+I134 -> 0
A10: Hospitality Bays | B10: 0 | C10: =D10/D8 -> #DIV/0! | D10: =E10/B10/$C30 -> #DIV/0! | E10: =E67+E89+E113+E135 -> 0 | F10: =F67+F89+F113+F135 -> 0 | G10: =H10/E10 -> #DIV/0! | H10: =H67+H89+H113+H135 -> 0 | I10: =I67+I89+I113+I135 -> 0
A11: TOTAL | B11: =SUM(B7:B10) -> 25 | D11: =E11/B11/$C30 -> 3052.1918 | E11: =SUM(E7:E10) -> 27851250 | F11: =SUM(F7:F10) -> 7588896.5 | G11: =H11/E11 -> 0.55120991 | H11: =SUM(H7:H10) -> 15351885 | I11: =SUM(I7:I10) -> 4183074.9
A12: Unescalated
A14: DISTINCT USERS | B14: # BAYS | C14: HOURS USED PER BAY | F14: NUMBER OF XRANGERS
C15: Daily | D15: Per Annum | E15: All Bays | F15: Users Per Bay | G15: Avg Time (Hrs) | H15: Xrangers | I15: Per Bay
A16: Mini-Bays | B16: =B7 -> 0 | C16: =(($G$28+$I$28)*$C$28/$C$30+($G$29+$I$29)*$C$29/$C$30)*G7 -> #DIV/0! | D16: =E16/B16 -> #DIV/0! | E16: =E73+E95+E119+E141 -> 0 | F16: =H16/E16*G16 -> #DIV/0! | G16: =(G141*H141+G119*H119+G95*H95+G73*H73)/H16 -> #DIV/0! | H16: =H73+H95+H119+H141 -> 0 | I16: =H16/B16 -> #DIV/0!
A17: Standard Bays | B17: =B8 -> 25 | C17: =(($G$28+$I$28)*$C$28/$C$30+($G$29+$I$29)*$C$29/$C$30)*G8 -> 8.428226 | D17: =E17/B17 -> 2803.148 | E17: =E74+E96+E120+E142 -> 70078.699 | F17: =H17/E17*G17 -> 4 | G17: =(G142*H142+G120*H120+G96*H96+G74*H74)/H17 -> 2 | H17: =H74+H96+H120+H142 -> 140157.4 | I17: =H17/B17 -> 5606.2959
A18: Premium Bays | B18: =B9 -> 0 | C18: =(($G$28+$I$28)*$C$28/$C$30+($G$29+$I$29)*$C$29/$C$30)*G9 -> #DIV/0! | D18: =E18/B18 -> #DIV/0! | E18: =E75+E97+E121+E143 -> 0 | F18: =H18/E18*G18 -> #DIV/0! | G18: =(G143*H143+G121*H121+G97*H97+G75*H75)/H18 -> #DIV/0! | H18: =H75+H97+H121+H143 -> 0 | I18: =H18/B18 -> #DIV/0!
A19: Hospitality Bays | B19: =B10 -> 0 | C19: =(($G$28+$I$28)*$C$28/$C$30+($G$29+$I$29)*$C$29/$C$30)*G10 -> #DIV/0! | D19: =E19/B19 -> #DIV/0! | E19: =E76+E98+E122+E144 -> 0 | F19: =H19/E19*G19 -> #DIV/0! | G19: =(G144*H144+G122*H122+G98*H98+G76*H76)/H19 -> #DIV/0! | H19: =H76+H98+H122+H144 -> 0 | I19: =H19/B19 -> #DIV/0!
A20: TOTAL | B20: =SUM(B16:B19) -> 25 | C20: =(($G$28+$I$28)*$C$28/$C$30+($G$29+$I$29)*$C$29/$C$30)*G11 -> 8.428226 | D20: =E20/B20 -> 2803.148 | E20: =SUM(E16:E19) -> 70078.699 | H20: =SUM(H16:H19) -> 140157.4 | I20: =H20/B20 -> 5606.2959
A23: BAY REVENUE USAGE & REVENUE ASSUMPTIONS
B24: AED | C24: USD
A25: Base Hourly Rate (Standard Bay) | B25: 200 | C25: =B25/'Financial Summary'!$E$3 -> 54.495913 | E25: Assumed Hours | F25: Weekdays | G25: 10am to 12am | H25: Weekdays | I25: 9am to 2am
A27: Facility Timing | B27: Distribution | C27: Total | E27: Peak / Non-Peak | F27: Non-Peak Hours | H27: Peak Hours
A28: Weekdays (M-T-W-TH) | B28: 4 | C28: =B28*52 -> 208 | E28: Weekdays | F28: 10 AM to 5PM | G28: 7 | H28: 5 PM to 12 AM | I28: 7
A29: Weekends (F-Sa-Su) | B29: 3 | C29: =B29*52+1 -> 157 | E29: Weekends | F29: 9 AM to 5 PM | G29: 8 | H29: 5 PM to 2 AM | I29: 9
C30: =SUM(C28:C29) -> 365
A32: Summary | B32: Vis/Day | C32: Vis/Bay/Day | D32: Daily Unique Visitors | E32: Bay Revenue | F32: Rev/Visitor
A33: Weekday Non-Peak | B33: =D33/C28 -> 72.814442 | C33: =B33/$B$68 -> 2.9125777 | D33: =H77 -> 15145.404 | E33: =H68 -> 1135905.3 | F33: =E33/D33 -> 75
A34: Weekday Peak | B34: =D34/C28 -> 145.62888 | C34: =B34/$B$68 -> 5.8251554 | D34: =H99 -> 30290.808 | E34: =H90 -> 3029080.8 | F34: =E34/D34 -> 100
A35: Weekday | B35: =D35/C28 -> 218.44333 | C35: =B35/$B$68 -> 8.737733 | D35: =SUM(D33:D34) -> 45436.212 | E35: =SUM(E33:E34) -> 4164986.1 | F35: =E35/D35 -> 91.666667
A36: Weekend Non-Peak | B36: =D36/C29 -> 166.43301 | C36: =B36/$B$68 -> 6.6573204 | D36: =H123 -> 26129.983 | E36: =H114 -> 2612998.3 | F36: =E36/D36 -> 100
A37: Weekend Peak | B37: =D37/C29 -> 436.88665 | C37: =B37/$B$68 -> 17.475466 | D37: =H145 -> 68591.204 | E37: =H136 -> 8573900.5 | F37: =E37/D37 -> 125
A38: Weekend | B38: =D38/C29 -> 603.31966 | C38: =B38/$B$68 -> 24.132786 | D38: =SUM(D36:D37) -> 94721.187 | E38: =SUM(E36:E37) -> 11186899 | F38: =E38/D38 -> 118.10345
A39: TOTALS | B39: =D39/C30 -> 383.99287 | C39: =B39/$B$68 -> 15.359715 | D39: =D35+D38 -> 140157.4 | E39: =E35+E38 -> 15351885 | F39: =E39/D39 -> 109.53318
A40: Non-Escalated
A42: Average Base Rates By Time | B42: =B24 -> AED | C42: =C24 -> USD | D42: Total Hours / Bay | E42: Mini-Bay | F42: Standard Bay | G42: Premium Bay | H42: Hospitality Bay | I42: Overall | K42: SENSITIVITY
A43: Weekday Non-Peak | B43: =B25*(1+B49+B51) -> 150 | C43: =B43/'Financial Summary'!$E$3 -> 40.871935 | D43: =G28*C28 -> 1456 | E43: =5%*(1+K43) -> 0.069347088 | F43: =15%*(1+K43) -> 0.20804126 | G43: =5%*(1+K43) -> 0.069347088 | H43: =5%*(1+K43) -> 0.069347088 | I43: =G68 -> 0.20804126 | K43: 0.38694175
A44: Weekday Peak | B44: =B25*(1+B49+B52) -> 200 | C44: =B44/'Financial Summary'!$E$3 -> 54.495913 | D44: =I28*C28 -> 1456 | E44: =20%*(1+K43) -> 0.27738835 | F44: =30%*(1+K43) -> 0.41608253 | G44: =20%*(1+K43) -> 0.27738835 | H44: =15%*(1+K43) -> 0.20804126 | I44: =G90 -> 0.41608253 | K44: ='Financial Summary'!B11 -> 140157.4
A45: Weekend Non-Peak | B45: =B25*(1+B50+B51) -> 200 | C45: =B45/'Financial Summary'!$E$3 -> 54.495913 | D45: =G29*C29 -> 1256 | E45: =30%*(1+K43) -> 0.41608253 | F45: =30%*(1+K43) -> 0.41608253 | G45: =20%*(1+K43) -> 0.27738835 | H45: =15%*(1+K43) -> 0.20804126 | I45: =G114 -> 0.41608253
A46: Weekend Peak | B46: =B25*(1+B50+B52) -> 250 | C46: =B46/'Financial Summary'!$E$3 -> 68.119891 | D46: =I29*C29 -> 1413 | E46: =50%*(1+K43) -> 0.69347088 | F46: =70%*(1+K43) -> 0.97085923 | G46: =55%*(1+K43) -> 0.76281796 | H46: =35%*(1+K43) -> 0.48542961 | I46: =G136 -> 0.97085923
E47: Bay Usage
A48: Peak / Non-Peak Adjustments | D48: Bay Rev Per Hour | E48: Mini-Bay | F48: Standard Bay | G48: Premium Bay | H48: Hospitality Bay | I48: Avg Hourly Rate
...

Sheet Hard + Soft Costs
A1: HARD COST SUMMARY | E1: ='Financial Summary'!M1 -> 45135
A3: Facility Size | B3: ='Area Schedule'!B32 -> 8652 | C3: =B3*'Area Schedule'!B3 -> 93130.128
A5: FACILITY HARD COST SUMMARY
A6: Main Facility | D6: AED psf GFA | E6: AED | F6: USD
A7: Substructure | D7: =E7/$C$3 -> 41.748037 | E7: =SUM(E45:E46) -> 3888000 | F7: =E7/'Financial Summary'!$E$3 -> 1059400.5
A8: Superstructure | D8: =E8/$C$3 -> 204.36485 | E8: =SUM(E9:E13) -> 19032525 | F8: =SUM(F9:F13) -> 5185974.1
A9: Structure | D9: =E9/$C$3 -> 54.413111 | E9: =SUM(E49:E57) -> 5067500 | F9: =E9/'Financial Summary'!$E$3 -> 1380790.2
A10: Roof | D10: =E10/$C$3 -> 45.168788 | E10: =SUM(E59:E64) -> 4206575 | F10: =E10/'Financial Summary'!$E$3 -> 1146205.7
A11: Stairs & Ramps | D11: =E11/$C$3 -> 2.6844159 | E11: =SUM(E66) -> 250000 | F11: =E11/'Financial Summary'!$E$3 -> 68119.891
A12: Façade | D12: =E12/$C$3 -> 79.422741 | E12: =SUM(E68:E79) -> 7396650 | F12: =E12/'Financial Summary'!$E$3 -> 2015436
A13: Internal Walls & Doors | D13: =E13/$C$3 -> 22.675798 | E13: =SUM(E80:E83) -> 2111800 | F13: =E13/'Financial Summary'!$E$3 -> 575422.34
A14: Finishes | D14: =E14/$C$3 -> 125.14962 | E14: =SUM(E87:E121) -> 11655200 | F14: =E14/'Financial Summary'!$E$3 -> 3175803.8
A15: MEP Installations | D15: =E15/$C$3 -> 206.55507 | E15: =SUM(E123:E125) -> 19236500 | F15: =E15/'Financial Summary'!$E$3 -> 5241553.1
A16: Total - Base Facility Cost | D16: =E16/$C$3 -> 577.81758 | E16: =E7+E8+E14+E15 -> 53812225 | F16: =F7+F8+F14+F15 -> 14662732
A17: Outfield | D17: =E17/$C$3 -> 107.37664 | E17: =E129 -> 10000000 | F17: =E17/'Financial Summary'!$E$3 -> 2724795.6
A18: Exterior Works | D18: =E18/$C$3 -> 82.680011 | E18: =E130 -> 7700000 | F18: =E18/'Financial Summary'!$E$3 -> 2098092.6
A19: Total - Base Facility Cost with Outfield & External Works | D19: =E19/$C$3 -> 767.87423 | E19: =SUM(E16:E18) -> 71512225 | F19: =SUM(F16:F18) -> 19485620
A20: Preliminaries | D20: =E20/$C$3 -> 65.269309 | E20: =E134 -> 6078539.1 | F20: =E20/'Financial Summary'!$E$3 -> 1656277.7
A21: Total Facility Cost w/ XRange Technology | D21: =E21/$C$3 -> 833.14354 | E21: =SUM(E19:E20) -> 77590764 | F21: =SUM(F19:F20) -> 21141898
A22: Contingency | D22: =E22/$C$3 -> 124.97153 | E22: =E138 -> 11638615 | F22: =E22/'Financial Summary'!$E$3 -> 3171284.6
A23: =A140 -> Regional Design Discount | D23: =E23/$C$3 -> -874.80071 | E23: =E140 -> -81470302
A24: TOTAL HARD COSTS | D24: =E24/$C$3 -> 83.314354 | E24: =SUM(E21:E23) -> 7759076.4 | F24: =SUM(F21:F22) -> 24313182
A26: XRANGE TECHNOLOGY COST SUMMARY
D27: AED psf GFA | E27: AED | F27: =F6 -> USD
A28: XRange Tech | D28: =E28/$C$3 -> 139.58963 | E28: =E150 -> 13000000 | F28: =E28/'Financial Summary'!$E$3 -> 3542234.3
A30: TOTAL XRANGE TECHNOLOGY COSTS | D30: =E30/$C$3 -> 139.58963 | E30: =SUM(E28:E29) -> 13000000 | F30: =SUM(F28:F29) -> 3542234.3
D31: AED psf GFA | E31: AED | F31: =F27 -> USD
A32: Design Costs - Facility, Outfield & Grounds (incl. contingency) | B32: on Facility Costs | C32: 0.12 | D32: =E32/$C$3 -> 9.9977224 | E32: =E24*C32 -> 931089.17 | F32: =E32/'Financial Summary'!$E$3 -> 253702.77
A33: Project Management Costs | B33: on Facility Costs | C33: 0.02 | D33: =E33/$C$3 -> 1.6662871 | E33: =E24*C33 -> 155181.53 | F33: =E33/'Financial Summary'!$E$3 -> 42283.795
A34: XRange Integration Fees (incl. in XRange Tech) | B34: on XRange Costs | C34: 0 | D34: =E34/$C$3 -> 0 | E34: =C34*E30 -> 0 | F34: =E34/'Financial Summary'!$E$3 -> 0
A36: TOTAL SOFT COSTS | D36: =E36/$C$3 -> 11.66401 | E36: =SUM(E32:E35) -> 1086270.7 | F36: =SUM(F32:F35) -> 295986.57
A41: ASSUMPTIONS
A43: Main Facility | B43: Quantity | C43: Unit | D43: Rate | E43: Total | F43: Total
A44: Substructure | E44: AED | F44: =F31 -> USD
A45: Raft slab to Ground Floor | B45: =SUM('Area Schedule'!B6:B11) -> 2598 | C45: m2 | D45: 1250 | E45: =D45*B45 -> 3247500 | F45: =E45/'Financial Summary'!$E$3 -> 884877.38
A46: Raft slab to Hitting Bays | B46: =SUM('Area Schedule'!B12:B13) -> 854 | C46: m2 | D46: 750 | E46: =D46*B46 -> 640500 | F46: =E46/'Financial Summary'!$E$3 -> 174523.16
A47: Superstructure
A48: Frame
A49: Columns to Ground Floor | B49: =SUM('Area Schedule'!B16:B20) -> 2600 | C49: m2 | D49: 300 | E49: =D49*B49 -> 780000 | F49: =E49/'Financial Summary'!$E$3 -> 212534.06
A50: Columns to Level 1 | B50: =SUM('Area Schedule'!B23:B29) -> 2600 | C50: m2 | D50: 300 | E50: =D50*B50 -> 780000 | F50: =E50/'Financial Summary'!$E$3 -> 212534.06
...

Sheet XRange Tech & Equipment
A1: XRANGE - SPECIALIST EQUIPMENT & TECH | E1: ='Financial Summary'!M1 -> 45135
A3: SUMMARY
A5: SPECIALIST EQUIPMENT | B5: QTY | C5: DESCRIPTION OF ITEM | D5: COST PER ITEM | E5: TOTAL COST | F5: COMMENTS
B6: # | D6: AED | E6: AED
A7: Right Hand Club Set | B7: 85 | C7: 12 Club Set - Branded | D7: 1400 | E7: =SUM(B7*D7) -> 119000
A8: Left Hand Club Set | B8: 25 | C8: 12 Club Branded Set - Branded | D8: 1500 | E8: =SUM(B8*D8) -> 37500
A9: Kids Right Hand Club Set | B9: 20 | C9: 12 Club Branded Set - Branded
A10: Kids Left Hand Club Set | B10: 10 | C10: 12 Club Branded Set - Branded
A11: Golf Balls | B11: 130 000 | C11: Branded Golf Balls
A12: Hopper H50, 50,000 ball cap. | B12: 85 | E12: =SUM(B12*D12) -> 0
A13: Elevator 2.3m hopper | B13: 85 | E13: =SUM(B13*D13) -> 0
A14: Automatic outfeed, Hopper-Blow | B14: 85 | E14: =SUM(B14*D14) -> 0
A15: Hopper H22 extended legs | B15: 85 | E15: =SUM(B15*D15) -> 0
A16: Blower Module 3.0 kW | B16: 85 | E16: =SUM(B16*D16) -> 0
A17: Blowfill manifold | B17: 85 | E17: =SUM(B17*D17) -> 0
A18: Ball stop, complete | B18: 85 | E18: =SUM(B18*D18) -> 0
A19: 6Photocell PNP V H&L level 1 | B19: 85 | E19: =SUM(B19*D19) -> 0
A20: Holder for photocell H/L ex. | B20: 85 | E20: =SUM(B20*D20) -> 0
A21: photocell | B21: 85 | E21: =SUM(B21*D21) -> 0
A22: Kabel Ölflex | B22: 85 | E22: =SUM(B22*D22) -> 0
A23: System Control Filling max | B23: 85 | E23: =SUM(B23*D23) -> 0
... A31: Tee Box Gen 4 | B31: 85 | E31: =SUM(B31*D31) -> 0
A39: TOTAL | B39: =SUM(B7:B31) -> 1840 | D39: =E39/B39/$C59 -> #DIV/0! | E39: =SUM(E7:E31) -> 156500
D45: XRange
E46: USD | F46: AED
B47: Tracking System | C47: Radar | E47: 300000 | F47: =SUM(#REF!*'Financial Summary'!E3) -> #REF!
B48: IT Infrustructure | C48: Server
B49: User Interface | C49: Control Panels
B50: Mega Media | C50: 3D Projection Mapping | D50: 4lg + 4sml Targets | E50: 2800000 | F50: =SUM(#REF!*'Financial Summary'!E3) -> #REF!
C52: Total
E54: 650000
E56: =SUM(E50+E54) -> 3450000

Sheet Area Schedule
A1: AREA SCHEDULE | B1: ='Financial Summary'!M1 -> 45135
A3: sm/sf | B3: 10.764
A5: GROUND FLOOR | B5: sm | C5: sf
A6: LOBBY AND PUBLIC CIRCULATION | B6: 647 | C6: =B6*$B$3 -> 6964.308
A7: MAIN RESTAURANT | B7: 997 | C7: =B7*$B$3 -> 10731.708
A8: TOILETS | B8: 144 | C8: =B8*$B$3 -> 1550.016
A9: ADMIN | B9: 170 | C9: =B9*$B$3 -> 1829.88
A10: BOH/MEP/KITCHEN | B10: 578 | C10: =B10*$B$3 -> 6221.592
A11: VT | B11: 62 | C11: =B11*$B$3 -> 667.368
A12: MINI BAYS - 10 BAYS | B12: 427 | C12: =B12*$B$3 -> 4596.228
A13: ACADEMY - 10 BAYS | B13: 427 | C13: =B13*$B$3 -> 4596.228
B14: =SUM(B6:B13) -> 3452 | C14: =SUM(C6:C13) -> 37157.328
A15: FIRST FLOOR
A16: PUBLIC CIRCULATION | B16: 460 | C16: =B16*$B$3 -> 4951.44
A17: TOILETS | B17: 144 | C17: =B17*$B$3 -> 1550.016
A18: BOH/MEP/KITCHEN | B18: 159 | C18: =B18*$B$3 -> 1711.476
A19: STANDARD BAYS - 42 BAYS | B19: 1775 | C19: =B19*$B$3 -> 19106.1
A20: VT | B20: 62 | C20: =B20*$B$3 -> 667.368
B21: =SUM(B16:B20) -> 2600 | C21: =SUM(C16:C20) -> 27986.4
A22: SECOND FLOOR
A23: PUBLIC CIRCULATION | B23: 460 | C23: =B23*$B$3 -> 4951.44
A24: TOILETS | B24: 144 | C24: =B24*$B$3 -> 1550.016
A25: BOH/MEP/KITCHEN | B25: 159 | C25: =B25*$B$3 -> 1711.476
A26: STANDARD BAYS - 14 BAYS | B26: 607 | C26: =B26*$B$3 -> 6533.748
A27: VIP - 4 BAYS | B27: 674 | C27: =B27*$B$3 -> 7254.936
A28: VVIP - 2 BAYS | B28: 494 | C28: =B28*$B$3 -> 5317.416
A29: VT | B29: 62 | C29: =B29*$B$3 -> 667.368
B30: =SUM(B23:B29) -> 2600 | C30: =SUM(C23:C29) -> 27986.4
A32: TOTAL | B32: =+B30+B21+B14 -> 8652 | C32: =+C30+C21+C14 -> 93130.128
A34: EXTERNAL WORKS
A35: PARKING / DROP OFF / LOADING AREA | B35: 14000 | C35: =B35*$B$3 -> 150696
A36: THE FIELD | B36: 20000 | C36: =B36*$B$3 -> 215280
A37: TOTAL | B37: =SUM(B35:B36) -> 34000 | C37: =SUM(C35:C36) -> 365976
A39: PROPERTY OF XRANGE
A40: Not For Distribution without the express agreement of XRange Management

Sheet Sheet1
