Workbook

Sheet Assumptions
A1: YOTEL + YOTELPAD BARBADOS | FINANCIAL MODEL
A2: Development Assumptions & Inputs — Coruscant Developments Ltd.
A4: PROJECT OVERVIEW
A5: Total Keys | B5: 130 | C5: 100 YOTEL SmartCabins + 30 YOTELPAD units
A6: YOTEL Rooms | B6: 100 | C6: SmartCabin ~145-170 sq ft
A7: YOTELPAD Units | B7: 30 | C7: Studios, 1BR, 2BR with kitchenettes
A8: Total Development Cost (USD) | B8: 32500000
A9: Cost per Key (USD) | B9: 250000
A10: Target Opening | B10: Q4 2027 | C10: 14-16 month modular programme from August 2026 construction start
A11: Exchange Rate (BBD:USD) | B11: 2 | C11: Fixed peg — 2 BBD = 1 USD
A13: DEVELOPMENT COST BREAKDOWN (USD)
A14: Cost Item | B14: USD Amount | C14: % of Total | D14: Notes
A15: Land Acquisition | B15: 3500000 | C15: =B15/B22 -> 0.10769231 | D15: Site on Bay Street, Bridgetown
A16: Site Work & Utilities | B16: 2200000 | C16: =B16/B22 -> 0.067692308 | D16: Limestone excavation, drainage, utility connections
A17: Prefab Modules (130 keys) | B17: 14300000 | C17: =B17/B22 -> 0.44 | D17: Factory fabrication + shipping (~65 x 40ft containers)
A18: Assembly & Construction | B18: 4550000 | C18: =B18/B22 -> 0.14 | D18: On-site crane lift, MEP connections, frame erection
A19: FF&E & Technology | B19: 3250000 | C19: =B19/B22 -> 0.1 | D19: SmartBeds, Technowalls, YOTEL tech stack
A20: Soft Costs (see detail below) | B20: 2600000 | C20: =B20/B22 -> 0.08 | D20: Architect, consultants, permits, legal, pre-opening
A21: Contingency (8%) | B21: 2100000 | C21: =B21/B22 -> 0.064615385 | D21: Budget risk buffer
A22: TOTAL DEVELOPMENT COST | B22: =SUM(B15:B21) -> 32500000 | C22: 100%
A24: SOFT COST DETAIL (USD) — real-world fee schedule
A25: Item | B25: Basis | C25: USD Amount | D25: % of Soft Costs | E25: Notes
A26: Architect Fees (5.5% of construction cost) | B26: 5.5% x BBD 58.5M | C26: 1608750 | D26: =C26/C38 -> 0.50109017 | E26: Excl. 17.5% VAT. Stages 1-4 per fee schedule
A27: Structural & MEP Engineers | B27: ~1.5% of construction | C27: 450000 | D27: =C27/C38 -> 0.14016508 | E27: Typically 25-30% of architect fee
A28: YOTEL Technical Services (TSA) | B28: Lump sum / day rates | C28: 150000 | D28: =C28/C38 -> 0.046721694 | E28: Brand review, TSA sign-off, mock-up inspection
A29: Project Manager / Owners Rep | B29: 2% of construction | C29: 380000 | D29: =C29/C38 -> 0.11836163 | E29: On-site PM through construction to opening
A30: Quantity Surveyor / Cost Consultant | B30: 0.5% of construction | C30: 95000 | D30: =C30/C38 -> 0.029590406 | E30: BCQS or equivalent; ongoing cost reporting
A31: Legal & Conveyancing | B31: Lump sum | C31: 80000 | D31: =C31/C38 -> 0.024918237 | E31: Land purchase, franchise agreement, lender docs
A32: Town Planning & EIA | B32: Lump sum | C32: 60000 | D32: =C32/C38 -> 0.018688678 | E32: Planning application, EIA screening & EIS
A33: Geotechnical Investigation | B33: 4 boreholes + report | C33: 17000 | D33: =C33/C38 -> 0.0052951254 | E33: BBD 25-35k; per feasibility study estimate
A34: Topographic & Boundary Survey | B34: Lump sum | C34: 10000 | D34: =C34/C38 -> 0.0031147796 | E34: Licensed surveyor to confirm net plot area
A35: Finance & Loan Arrangement Fees | B35: ~1% of debt | C35: 250000 | D35: =C35/C38 -> 0.077869491 | E35: Senior + mezzanine arrangement; Eastdil/lender
A36: Pre-Opening Marketing & Sales | B36: Lump sum | C36: 150000 | D36: =C36/C38 -> 0.046721694 | E36: Brand launch, digital, OTA setup, PR
A37: Miscellaneous / Contingency | B37: Residual | C37: -40250 | D37: =C37/C38 -> -0.012536988 | E37: Balances total soft costs to $2,600,000
A38: TOTAL SOFT COSTS | C38: =SUM(C26:C37) -> 3210500
A40: REVENUE ASSUMPTIONS
B41: Year 1 | C41: Year 2 | D41: Year 3 | E41: Year 4 | F41: Year 5
A42: YOTEL (100 Rooms)
A43: ADR (USD) | B43: 155 | C43: 185 | D43: 195 | E43: 203 | F43: 211
A44: Occupancy % | B44: 0.55 | C44: 0.72 | D44: 0.78 | E44: 0.78 | F44: 0.79
...

Sheet 10-Year Proforma
A1: YOTEL + YOTELPAD BARBADOS | 10-YEAR OPERATING PROFORMA (USD)
A2: All figures in USD. Blue = Assumptions sheet input. Black = formula. Year 1 = first full operating year from Q4 2027 opening.
A4: Line Item | B4: Year 1 | C4: Year 2 | D4: Year 3 | E4: Year 4 | F4: Year 5 | G4: Year 6 | H4: Year 7 | I4: Year 8 | J4: Year 9 | K4: Year 10
A5: REVENUE
A6: YOTEL Rooms Revenue | B6: =Assumptions!B43*Assumptions!B46 -> 3111625 | C6: =Assumptions!C43*Assumptions!C46 -> 4861800 | D6: =Assumptions!D43*Assumptions!D46 -> 5551650 | E6: =Assumptions!E43*Assumptions!E46 -> 5779410 | F6: =Assumptions!F43*Assumptions!F46 -> 6084185 | G6: =F6*(1+0.04) -> 6327552.4 | H6: =G6*(1+0.04) -> 6580654.5 | I6: =H6*(1+0.04) -> 6843880.7 | J6: =I6*(1+0.04) -> 7117635.9 | K6: =J6*(1+0.04) -> 7402341.3
A7: YOTELPAD Rooms Revenue | B7: =Assumptions!B48*Assumptions!B51 -> 1445400 | C7: =Assumptions!C48*Assumptions!C51 -> 2010420 | D7: =Assumptions!D48*Assumptions!D51 -> 2217510 | E7: =Assumptions!E48*Assumptions!E51 -> 2307853 | F7: =Assumptions!F48*Assumptions!F51 -> 2430024 | G7: =F7*(1+0.04) -> 2527225 | H7: =G7*(1+0.04) -> 2628314 | I7: =H7*(1+0.04) -> 2733446.5 | J7: =I7*(1+0.04) -> 2842784.4 | K7: =J7*(1+0.04) -> 2956495.8
A8: Total Rooms Revenue | B8: =B6+B7 -> 4557025 | C8: =C6+C7 -> 6872220 | D8: =D6+D7 -> 7769160 | E8: =E6+E7 -> 8087263 | F8: =F6+F7 -> 8514209 | G8: =G6+G7 -> 8854777.4 | H8: =H6+H7 -> 9208968.5 | I8: =I6+I7 -> 9577327.2 | ... K8: =K6+K7 -> 10358837
A9: Combined Occupied Nights (YOTEL + YOTELPAD) | B9: =Assumptions!B46+Assumptions!B51 -> 26645 | C9: =Assumptions!C46+Assumptions!C51 -> 34164 | D9: =Assumptions!D46+Assumptions!D51 -> 36683 | E9: =Assumptions!E46+Assumptions!E51 -> 36683 | F9: =Assumptions!F46+Assumptions!F51 -> 37157 | G9: =F9*(1+0.01) -> 37528.57 | H9: =G9*(1+0.01) -> 37903.856 | I9: =H9*(1+0.01) -> 38282.894 | J9: =I9*(1+0.01) -> 38665.723 | K9: =J9*(1+0.01) -> 39052.38
A10: F&B Revenue | B10: =B9*Assumptions!B53 -> 1199025 | C10: =C9*Assumptions!C53 -> 1537380 | D10: =D9*Assumptions!D53 -> 1650735 | E10: =E9*Assumptions!E53 -> 1650735 | F10: =F9*Assumptions!F53 -> 1672065 | G10: =F10*(1+0.04) -> 1738947.6 | H10: =G10*(1+0.04) -> 1808505.5 | I10: =H10*(1+0.04) -> 1880845.7 | J10: =I10*(1+0.04) -> 1956079.6 | K10: =J10*(1+0.04) -> 2034322.7
A11: Other Revenue (Podcast, Gym, Sim — 0% YOTEL fee) | B11: =B9*Assumptions!B54 -> 319740 | C11: =C9*Assumptions!C54 -> 409968 | D11: =D9*Assumptions!D54 -> 440196 | E11: =E9*Assumptions!E54 -> 440196 | F11: =F9*Assumptions!F54 -> 445884 | G11: =F11*(1+0.04) -> 463719.36 | H11: =G11*(1+0.04) -> 482268.13 | I11: =H11*(1+0.04) -> 501558.86 | J11: =I11*(1+0.04) -> 521621.21 | K11: =J11*(1+0.04) -> 542486.06
A12: TOTAL REVENUE | B12: =B8+B10+B11 -> 6075790 | C12: =C8+C10+C11 -> 8819568 | D12: =D8+D10+D11 -> 9860091 | E12: =E8+E10+E11 -> 10178194 | F12: =F8+F10+F11 -> 10632158 | G12: =G8+G10+G11 -> 11057444 | H12: =H8+H10+H11 -> 11499742 | I12: =I8+I10+I11 -> 11959732 | ... K12: =K8+K10+K11 -> 12935646
A14: OPERATING EXPENSES
A15: Rooms Expense (18% of Rooms Revenue) | B15: =B8*Assumptions!$B$57 -> 820264.5 | C15: =C8*Assumptions!$B$57 -> 1236999.6 | D15: =D8*Assumptions!$B$57 -> 1398448.8 | E15: =E8*Assumptions!$B$57 -> 1455707.3 | F15: =F8*Assumptions!$B$57 -> 1532557.6 | G15: =G8*Assumptions!$B$57 -> 1593859.9 | H15: =H8*Assumptions!$B$57 -> 1657614.3 | I15: =I8*Assumptions!$B$57 -> 1723918.9 | ... K15: =K8*Assumptions!$B$57 -> 1864590.7
A16: F&B Expense (60% of F&B Revenue) | B16: =B10*0.6 -> 719415 | C16: =C10*0.6 -> 922428 | D16: =D10*0.6 -> 990441 | E16: =E10*0.6 -> 990441 | F16: =F10*0.6 -> 1003239 | G16: =G10*0.6 -> 1043368.6 | H16: =H10*0.6 -> 1085103.3 | I16: =I10*0.6 -> 1128507.4 | ... K16: =K10*0.6 -> 1220593.6
A17: Staff Costs (18% of Total Revenue | B17: =B12*0.18 -> 1093642.2 | C17: =C12*0.18 -> 1587522.2 | D17: =D12*0.18 -> 1774816.4 | E17: =E12*0.18 -> 1832074.9 | F17: =F12*0.18 -> 1913788.4 | G17: =G12*0.18 -> 1990340 | H17: =H12*0.18 -> 2069953.6 | I17: =I12*0.18 -> 2152751.7 | ... K17: =K12*0.18 -> 2328416.3
A18: OTA Commissions (5% of Total Revenue | B18: =B12*Assumptions!$B$61 -> 303789.5 | C18: =C12*Assumptions!$B$61 -> 440978.4 | D18: =D12*Assumptions!$B$61 -> 493004.55 | E18: =E12*Assumptions!$B$61 -> 508909.7 | F18: =F12*Assumptions!$B$61 -> 531607.9 | G18: =G12*Assumptions!$B$61 -> 552872.22 | H18: =H12*Assumptions!$B$61 -> 574987.1 | I18: =I12*Assumptions!$B$61 -> 597986.59 | ... K18: =K12*Assumptions!$B$61 -> 646782.29
A19: Sales & Marketing (3% of Total Revenue) | B19: =B12*0.03 -> 182273.7 | C19: =C12*0.03 -> 264587.04 | D19: =D12*0.03 -> 295802.73 | E19: =E12*0.03 -> 305345.82 | F19: =F12*0.03 -> 318964.74 | G19: =G12*0.03 -> 331723.33 | H19: =H12*0.03 -> 344992.26 | I19: =I12*0.03 -> 358791.95 | ... K19: =K12*0.03 -> 388069.38
A20: G&A — Fixed (escalating 3% p.a.) | B20: 650000 | C20: =B20*1.03 -> 669500 | D20: =C20*1.03 -> 689585 | E20: =D20*1.03 -> 710272.55 | F20: =E20*1.03 -> 731580.73 | G20: =F20*1.03 -> 753528.15 | H20: =G20*1.03 -> 776133.99 | I20: =H20*1.03 -> 799418.01 | J20: =I20*1.03 -> 823400.55 | K20: =J20*1.03 -> 848102.57
A21: POM & Utilities (5% of Total Revenue) | B21: =B12*0.05 -> 303789.5 | C21: =C12*0.05 -> 440978.4 | D21: =D12*0.05 -> 493004.55 | E21: =E12*0.05 -> 508909.7 | F21: =F12*0.05 -> 531607.9 | G21: =G12*0.05 -> 552872.22 | H21: =H12*0.05 -> 574987.1 | I21: =I12*0.05 -> 597986.59 | ... K21: =K12*0.05 -> 646782.29
A22: YOTEL Base Management Fee (7.5% of Total Revenue) | B22: =B12*Assumptions!$B$66 -> 455684.25 | C22: =C12*Assumptions!$B$66 -> 661467.6 | D22: =D12*Assumptions!$B$66 -> 739506.82 | E22: =E12*Assumptions!$B$66 -> 763364.55 | F22: =F12*Assumptions!$B$66 -> 797411.85 | G22: =G12*Assumptions!$B$66 -> 829308.32 | H22: =H12*Assumptions!$B$66 -> 862480.66 | I22: =I12*Assumptions!$B$66 -> 896979.88 | ... K22: =K12*Assumptions!$B$66 -> 970173.44
A23: YOTEL Royalty & Brand Fee (5% of Total Revenue) | B23: =B12*Assumptions!$B$67 -> 303789.5 | C23: =C12*Assumptions!$B$67 -> 440978.4 | D23: =D12*Assumptions!$B$67 -> 493004.55 | E23: =E12*Assumptions!$B$67 -> 508909.7 | F23: =F12*Assumptions!$B$67 -> 531607.9 | G23: =G12*Assumptions!$B$67 -> 552872.22 | H23: =H12*Assumptions!$B$67 -> 574987.1 | I23: =I12*Assumptions!$B$67 -> 597986.59 | ... K23: =K12*Assumptions!$B$67 -> 646782.29
A24: YOTEL System & Technology Fee (3% of Total Revenue) | B24: =B12*Assumptions!$B$68 -> 182273.7 | C24: =C12*Assumptions!$B$68 -> 264587.04 | D24: =D12*Assumptions!$B$68 -> 295802.73 | E24: =E12*Assumptions!$B$68 -> 305345.82 | F24: =F12*Assumptions!$B$68 -> 318964.74 | G24: =G12*Assumptions!$B$68 -> 331723.33 | H24: =H12*Assumptions!$B$68 -> 344992.26 | I24: =I12*Assumptions!$B$68 -> 358791.95 | ... K24: =K12*Assumptions!$B$68 -> 388069.38
A25: YOTEL F&B Fee (1.5% of F&B Revenue ) | B25: =B10*Assumptions!$B$69 -> 17985.375 | C25: =C10*Assumptions!$B$69 -> 23060.7 | D25: =D10*Assumptions!$B$69 -> 24761.025 | E25: =E10*Assumptions!$B$69 -> 24761.025 | F25: =F10*Assumptions!$B$69 -> 25080.975 | G25: =G10*Assumptions!$B$69 -> 26084.214 | H25: =H10*Assumptions!$B$69 -> 27127.583 | I25: =I10*Assumptions!$B$69 -> 28212.686 | ... K25: =K10*Assumptions!$B$69 -> 30514.841
A26: TOTAL OPERATING EXPENSES | B26: =B15+B16+B17+B18+B19+B20+B21+B22+B23+B24+B25 -> 5032907.2 | C26: =C15+C16+C17+C18+C19+C20+C21+C22+C23+C24+C25 -> 6953087.4 | D26: =D15+D16+D17+D18+D19+D20+D21+D22+D23+D24+D25 -> 7688178.1 | E26: =E15+E16+E17+E18+E19+E20+E21+E22+E23+E24+E25 -> 7914042.1 | F26: =F15+F16+F17+F18+F19+F20+F21+F22+F23+F24+F25 -> 8236411.8 | G26: =G15+G16+G17+G18+G19+G20+G21+G22+G23+G24+G25 -> 8558552.5 | H26: =H15+H16+H17+H18+H19+H20+H21+H22+H23+H24+H25 -> 8893359.3 | I26: =I15+I16+I17+I18+I19+I20+I21+I22+I23+I24+I25 -> 9241332.3 | ... K26: =K15+K16+K17+K18+K19+K20+K21+K22+K23+K24+K25 -> 9978877.1
A27: GROSS OPERATING PROFIT (GOP) | B27: =B12-B26 -> 1042882.8 | C27: =C12-C26 -> 1866480.6 | D27: =D12-D26 -> 2171912.9 | E27: =E12-E26 -> 2264151.9 | F27: =F12-F26 -> 2395746.2 | G27: =G12-G26 -> 2498891.9 | H27: =H12-H26 -> 2606382.8 | I27: =I12-I26 -> 2718399.5 | ... K27: =K12-K26 -> 2956768.8
A28: GOP Margin % | B28: =IF(B12<>0,B27/B12,0) -> 0.17164563 | C28: =IF(C12<>0,C27/C12,0) -> 0.21162948 | D28: =IF(D12<>0,D27/D12,0) -> 0.2202731 | E28: =IF(E12<>0,E27/E12,0) -> 0.22245124 | F28: =IF(F12<>0,F27/F12,0) -> 0.22533019 | G28: =IF(G12<>0,G27/G12,0) -> 0.22599181 | H28: =IF(H12<>0,H27/H12,0) -> 0.22664707 | I28: =IF(I12<>0,I27/I12,0) -> 0.22729602 | ... K28: =IF(K12<>0,K27/K12,0) -> 0.22857528
A30: BELOW-GOP CHARGES
A31: FF&R Reserve (3% of Total Revenue) | B31: =B12*0.03 -> 182273.7 | C31: =C12*0.03 -> 264587.04 | D31: =D12*0.03 -> 295802.73 | E31: =E12*0.03 -> 305345.82 | F31: =F12*0.03 -> 318964.74 | G31: =G12*0.03 -> 331723.33 | H31: =H12*0.03 -> 344992.26 | I31: =I12*0.03 -> 358791.95 | ... K31: =K12*0.03 -> 388069.38
A32: Insurance & Taxes — Fixed (escalating 3% p.a.) | B32: 475000 | C32: =B32*1.03 -> 489250 | D32: =C32*1.03 -> 503927.5 | E32: =D32*1.03 -> 519045.33 | F32: =E32*1.03 -> 534616.68 | G32: =F32*1.03 -> 550655.19 | H32: =G32*1.03 -> 567174.84 | I32: =H32*1.03 -> 584190.09 | J32: =I32*1.03 -> 601715.79 | K32: =J32*1.03 -> 619767.26
A33: NET OPERATING INCOME (NOI) | B33: =B27-B31-B32 -> 385609.07 | C33: =C27-C31-C32 -> 1112643.5 | D33: =D27-D31-D32 -> 1372182.6 | E33: =E27-E31-E32 -> 1439760.7 | F33: =F27-F31-F32 -> 1542164.8 | G33: =G27-G31-G32 -> 1616513.3 | H33: =H27-H31-H32 -> 1694215.7 | I33: =I27-I31-I32 -> 1775417.4 | ... K33: =K27-K31-K32 -> 1948932.2
A34: NOI Margin % | B34: =IF(B12<>0,B33/B12,0) -> 0.063466492 | C34: =IF(C12<>0,C33/C12,0) -> 0.12615624 | D34: =IF(D12<>0,D33/D12,0) -> 0.13916531 | E34: =IF(E12<>0,E33/E12,0) -> 0.14145542 | F34: =IF(F12<>0,F33/F12,0) -> 0.1450472 | G34: =IF(G12<>0,G33/G12,0) -> 0.14619231 | H34: =IF(H12<>0,H33/H12,0) -> 0.14732641 | I34: =IF(I12<>0,I33/I12,0) -> 0.1484496 | ... K34: =IF(K12<>0,K33/K12,0) -> 0.15066369
A36: DEBT SERVICE
A37: Senior Debt Interest (6.5% on $20M — interest only) | B37: =Assumptions!$B$77*Assumptions!$C$77 -> 1300000 | C37: =Assumptions!$B$77*Assumptions!$C$77 -> 1300000 | D37: =Assumptions!$B$77*Assumptions!$C$77 -> 1300000 | E37: =Assumptions!$B$77*Assumptions!$C$77 -> 1300000 | F37: =Assumptions!$B$77*Assumptions!$C$77 -> 1300000 | G37: =Assumptions!$B$77*Assumptions!$C$77 -> 1300000 | H37: =Assumptions!$B$77*Assumptions!$C$77 -> 1300000 | I37: =Assumptions!$B$77*Assumptions!$C$77 -> 1300000 | ... K37: =Assumptions!$B$77*Assumptions!$C$77 -> 1300000
A38: Mezzanine Interest (11% PIK on $5M) | B38: =Assumptions!$B$78*Assumptions!$C$78 -> 550000 | C38: =Assumptions!$B$78*Assumptions!$C$78 -> 550000 | D38: =Assumptions!$B$78*Assumptions!$C$78 -> 550000 | E38: =Assumptions!$B$78*Assumptions!$C$78 -> 550000 | F38: =Assumptions!$B$78*Assumptions!$C$78 -> 550000 | G38: =Assumptions!$B$78*Assumptions!$C$78 -> 550000 | H38: =Assumptions!$B$78*Assumptions!$C$78 -> 550000 | I38: =Assumptions!$B$78*Assumptions!$C$78 -> 550000 | ... K38: =Assumptions!$B$78*Assumptions!$C$78 -> 550000
A39: Total Debt Service | B39: =B37+B38 -> 1850000 | C39: =C37+C38 -> 1850000 | D39: =D37+D38 -> 1850000 | E39: =E37+E38 -> 1850000 | F39: =F37+F38 -> 1850000 | G39: =G37+G38 -> 1850000 | H39: =H37+H38 -> 1850000 | I39: =I37+I38 -> 1850000 | ... K39: =K37+K38 -> 1850000
A40: CASH FLOW BEFORE TAX (NOI less Debt Service) | B40: =B33-B39 -> -1464390.9 | C40: =C33-C39 -> -737356.46 | D40: =D33-D39 -> -477817.37 | E40: =E33-E39 -> -410239.27 | F40: =F33-F39 -> -307835.22 | G40: =G33-G39 -> -233486.65 | H40: =H33-H39 -> -155784.28 | I40: =I33-I39 -> -74582.566 | ... K40: =K33-K39 -> 98932.184
A41: DSCR (NOI / Debt Service) | B41: =IF(B39<>0,B33/B39,0) -> 0.20843734 | C41: =IF(C39<>0,C33/C39,0) -> 0.60142894 | D41: =IF(D39<>0,D33/D39,0) -> 0.74172034 | E41: =IF(E39<>0,E33/E39,0) -> 0.77824904 | F41: =IF(F39<>0,F33/F39,0) -> 0.83360259 | G41: =IF(G39<>0,G33/G39,0) -> 0.873791 | H41: =IF(H39<>0,H33/H39,0) -> 0.91579228 | I41: =IF(I39<>0,I33/I39,0) -> 0.9596851 | ... K41: =IF(K39<>0,K33/K39,0) -> 1.0534769

Sheet Returns Analysis
A1: YOTEL + YOTELPAD BARBADOS | RETURNS ANALYSIS (USD)
A2: All figures in USD. Sources: 10-Year Proforma sheet.
A4: CAPITAL STRUCTURE
A5: Total Development Cost (USD) | B5: =Assumptions!$B$22 -> 32500000
A6: Senior Debt (USD) | B6: =Assumptions!$B$77 -> 20000000
A7: Senior Interest Rate | B7: =Assumptions!$C$77 -> 0.065
A8: Mezzanine Debt (USD) | B8: =Assumptions!$B$78 -> 5000000
A9: Mezzanine Rate (PIK) | B9: =Assumptions!$C$78 -> 0.11
A10: Equity (USD) | B10: =Assumptions!$B$79 -> 7500000
A11: LTV Ratio (Senior / Total Cost) | B11: =B6/B5 -> 0.61538462
A13: KEY YEAR METRICS (from 10-Year Proforma)
A14: Metric | B14: Year 1 | C14: Year 3 | D14: Year 5 | E14: Year 7 | F14: Year 10
A15: Total Revenue | B15: ='10-Year Proforma'!B12 -> 6075790 | C15: ='10-Year Proforma'!D12 -> 9860091 | D15: ='10-Year Proforma'!F12 -> 10632158 | E15: ='10-Year Proforma'!H12 -> 11499742 | F15: ='10-Year Proforma'!K12 -> 12935646
A16: GOP | B16: ='10-Year Proforma'!B27 -> 1042882.8 | C16: ='10-Year Proforma'!D27 -> 2171912.9 | D16: ='10-Year Proforma'!F27 -> 2395746.2 | E16: ='10-Year Proforma'!H27 -> 2606382.8 | F16: ='10-Year Proforma'!K27 -> 2956768.8
A17: GOP Margin % | B17: ='10-Year Proforma'!B28 -> 0.17164563 | C17: ='10-Year Proforma'!D28 -> 0.2202731 | D17: ='10-Year Proforma'!F28 -> 0.22533019 | E17: ='10-Year Proforma'!H28 -> 0.22664707 | F17: ='10-Year Proforma'!K28 -> 0.22857528
A18: NOI (Proforma) | B18: ='10-Year Proforma'!B33 -> 385609.07 | C18: ='10-Year Proforma'!D33 -> 1372182.6 | D18: ='10-Year Proforma'!F33 -> 1542164.8 | E18: ='10-Year Proforma'!H33 -> 1694215.7 | F18: ='10-Year Proforma'!K33 -> 1948932.2
A19: NOI Margin % | B19: ='10-Year Proforma'!B34 -> 0.063466492 | C19: ='10-Year Proforma'!D34 -> 0.13916531 | D19: ='10-Year Proforma'!F34 -> 0.1450472 | E19: ='10-Year Proforma'!H34 -> 0.14732641 | F19: ='10-Year Proforma'!K34 -> 0.15066369
A20: Total Debt Service | B20: ='10-Year Proforma'!B39 -> 1850000 | C20: ='10-Year Proforma'!D39 -> 1850000 | D20: ='10-Year Proforma'!F39 -> 1850000 | E20: ='10-Year Proforma'!H39 -> 1850000 | F20: ='10-Year Proforma'!K39 -> 1850000
A21: Cash Flow Before Tax | B21: ='10-Year Proforma'!B40 -> -1464390.9 | C21: ='10-Year Proforma'!D40 -> -477817.37 | D21: ='10-Year Proforma'!F40 -> -307835.22 | E21: ='10-Year Proforma'!H40 -> -155784.28 | F21: ='10-Year Proforma'!K40 -> 98932.184
A22: DSCR | B22: ='10-Year Proforma'!B41 -> 0.20843734 | C22: ='10-Year Proforma'!D41 -> 0.74172034 | D22: ='10-Year Proforma'!F41 -> 0.83360259 | E22: ='10-Year Proforma'!H41 -> 0.91579228 | F22: ='10-Year Proforma'!K41 -> 1.0534769
A24: EXIT ANALYSIS — STABILISED YEAR 5 (from opening Q4 2027)
A25: Exit Cap Rate | B25: 0.085
A26: Stabilised Year 5 NOI (per Treasury Model) | B26: 3864055
A27: Gross Property Value at Exit (Stabilised NOI / Cap Rate) | B27: =B26/B25 -> 45459471
A28: Less: Outstanding Senior Debt | B28: 20000000
A29: Less: Outstanding Mezzanine Debt (PIK accrued) | B29: 5000000 | C29: Note: PIK compounds; negotiate repayment terms with lender
A30: Net Sale Proceeds to Equity | B30: =B27-B28-B29 -> 20459471
A32: RETURNS SUMMARY
A33: Initial Equity Investment (USD) | B33: =Assumptions!$B$79 -> 7500000
A34: Year 10 Net Sale Proceeds | B34: =B30 -> 20459471
A35: Equity Multiple (Net Proceeds / Initial Equity) | B35: =B34/B33 -> 2.7279294
A36: Year 5 Cash Flow Yield on Equity | B36: =IF(B33<>0,'10-Year Proforma'!F40/B33,0) -> -0.041044696
A37: Levered IRR (Target Range) | B37: 17-21% | C37: Confirmed range per investment materials; verify with IRR() once cash flows finalised
A39: NOI SENSITIVITY — Year 3 Stabilised (Occupancy vs ADR)
A40: ADR / Occ % | B40: 65% Occ | C40: 70% Occ | D40: 75% Occ | E40: 80% Occ | F40: 85% Occ
A41: ADR $165 | B41: 932762 | C41: 1089855 | D41: 1246948 | E41: 1404120 | F41: 1561292
A42: ADR $180 | B42: 1072268 | C42: 1240089 | D42: 1407910 | E42: 1575816 | F42: 1743722
A43: ADR $195 | B43: 1213767 | C43: 1392469 | D43: 1571171 | E43: 1749965 | F43: 1928758
A44: ADR $210 | B44: 1355266 | C44: 1544849 | D44: 1734433 | E44: 1924114 | F44: 2113794
A45: ADR $225 | B45: 1494772 | C45: 1695083 | D45: 1895395 | E45: 2095810 | F45: 2296224
...

Sheet Soft Cost Phasing
A1: SOFT COST PHASING | Architect Fee Drawdown & Professional Fees (USD)
A2: Based on architect fee schedule (5.5% of BD$58.5M = BD$3,217,500 = USD$1,608,750 excl. VAT 17.5%)
A4: ARCHITECT FEE DRAWDOWN (per Stage Schedule)
A5: Stage | B5: % of Fee | C5: BD$ Amount | D5: USD Amount | E5: VAT 17.5% (BD$) | F5: When Due | G5: Status
A6: Retainer / Stage 1a — Preliminary sketch design | B6: 0.1 | C6: 321750 | D6: 160875 | E6: 56306 | F6: At inception / contract signing | G6: Due now
A7: Stage 1b — Preliminary finalised | B7: 0.15 | C7: 482625 | D7: 241313 | E7: 84459 | F7: End of Stage 1 | G7: Pending
A8: Stage 2 — Design Development + Planning submission | B8: 0.25 | C8: 804375 | D8: 402188 | E8: 140766 | F8: End of Stage 2 | G8: Pending
A9: Stage 3 — Construction Drawings / IFC | B9: 0.4 | C9: 1287000 | D9: 643500 | E9: 225225 | F9: End of Stage 3 | G9: Pending
A10: Stage 4 — Contract Administration (site inspections) | B10: 0.1 | C10: 321750 | D10: 160875 | E10: 56306 | F10: During & end of construction | G10: Pending
A11: TOTAL ARCHITECT FEE (excl. VAT) | C11: 3217500 | D11: 1608750 | E11: 562307 | F11: VAT recoverable as input tax
A13: FULL PROFESSIONAL FEES SUMMARY (USD)
A14: Consultant | B14: USD Fee | C14: Basis | D14: Payment Trigger
A15: Architect (5.5% of construction cost) | B15: 1608750 | C15: 5.5% x BD$58.5M / 2 | D15: Stage drawdowns per above
A16: Structural & MEP Engineers | B16: 450000 | C16: ~1.5% of construction | D16: Design milestones
A17: YOTEL Technical Services (TSA) | B17: 150000 | C17: Lump sum / day rates | D17: Brand review gates
A18: Project Manager / Owners Rep | B18: 380000 | C18: 2% of construction | D18: Monthly during construction
A19: Quantity Surveyor | B19: 95000 | C19: 0.5% of construction | D19: Ongoing; reporting monthly
A20: Legal & Conveyancing | B20: 80000 | C20: Lump sum | D20: Land close + franchise sign
A21: Town Planning & EIA | B21: 60000 | C21: Lump sum | D21: Pre-planning submission
A22: Geotechnical Investigation | B22: 17000 | C22: 4 boreholes per feasibility | D22: Month 1 — before design
A23: Topographic & Boundary Survey | B23: 10000 | C23: Lump sum | D23: Immediate — open item
A24: Finance / Loan Arrangement Fees | B24: 250000 | C24: ~1% of $25M debt | D24: At financial close
A25: Pre-Opening Marketing | B25: 150000 | C25: Lump sum | D25: 3-6 months before opening
A26: TOTAL PROFESSIONAL FEES | B26: 3250750
