Workbook

Sheet Fund Assumptions
A1: YOTEL + YOTELPAD BARBADOS | MAGNUS CAPITAL STRUCTURE | TREASURY MANAGEMENT & WATERFALL MODEL
A2: Single-site Barbados analysis | Coruscant Developments Ltd. | Confidential
A4: CAPITAL STRUCTURE (Barbados single site)
A5: Item | B5: USD Amount | C5: % of Stack | D5: Notes
A6: Total Development Cost | B6: 32500000 | D6: Fixed; per project budget
A7: Senior Debt | B7: 20000000 | C7: =B7/B6 -> 0.61538462 | D7: 6.5% interest-only; Caribbean institutional lender
A8: Mezzanine Debt | B8: 5000000 | C8: =B8/B6 -> 0.15384615 | D8: 11% PIK; negotiate cash-pay vs compounding
A9: Total LP Equity Required | B9: =B6-B7-B8 -> 7500000 | C9: =B9/B6 -> 0.23076923 | D9: To be raised via Magnus 506C fund structure
A10: of which: Coruscant GP Co-invest (target) | B10: 500000 | D10: GP co-invest to align with LP investors
A11: of which: LP Capital (third-party raise) | B11: =B9-B10 -> 7000000
A13: TREASURY MANAGEMENT ASSUMPTIONS (Phil / Magnus call)
A14: Parameter | B14: Value | C14: Basis | D14: Notes
A15: LP Capital Called at Closing (Month 0) | B15: 7000000 | D15: Phil proposed calling full equity upfront; use 7M as base case (total equity less GP co-invest)
A16: Treasury Yield Rate (annualised) | B16: 0.1 | D16: Phil stated up to $83k/month on $10M = ~10% p.a. Verify with RIA before committing
A17: Monthly Treasury Yield on Parked Capital | B17: =B15*B16/12 -> 58333.333 | D17: Max monthly yield (Month 0 balance). Actual monthly yield declines as capital is drawn.
A18: Pre-Opening Period (months; capital parked) | B18: 16 | D18: Months 1-16 from August 2026; capital deployed into construction per drawdown schedule. Opening target Q4 2027.
A19: Capital Deployed per Month (avg construction draw) | B19: =B15/B18 -> 437500 | D19: Simplification; actual drawdown is back-loaded. See Drawdown tab.
A20: Total APR Paid to LPs over Pre-Opening | B20: ='Treasury Cashflow'!F21 -> 489999.99 | D20: Actual total yield from Treasury Cashflow tab (yield earned on declining balance as draws occur)
A22: LP PREFERRED RETURN & WATERFALL ASSUMPTIONS
A23: LP Preferred Return (hurdle rate) | B23: 0.08 | D23: Annual cash return LPs must receive before GP participates in profits
A24: LP Share of Distributable Income (above hurdle) | B24: 0.7 | D24: Phil: standard 70/30 LP/GP split on distributions above preferred return
A25: GP Share of Distributable Income (carry) | B25: =1-B24 -> 0.3 | D25: 30% GP carry; Magnus takes 10-15% of this GP slice
A26: Magnus Share of GP Carry | B26: 0.125 | D26: Phil stated 10-15%; using 12.5% midpoint. Verify in term sheet.
A27: Coruscant Share of GP Carry | B27: =1-B26 -> 0.875 | D27: 87.5% of the 30% GP slice
A29: EXIT ASSUMPTIONS
A30: Exit Year | B30: 5 | D30: Phil suggested Year 5 portfolio exit; single-site modelled here
A31: Year 5 NOI (from main financial model) | B31: 3864055 | D31: Source: YOTEL Barbados Financial Model v2, Year 5 NOI. Update when model finalised.
A32: Exit Cap Rate | B32: 0.085 | D32: 8.5% Caribbean hotel cap rate; consistent with main model
A33: Gross Exit Property Value (NOI / Cap Rate) | B33: =IF(B32<>0,B31/B32,0) -> 45459471 | D33: Implied valuation at exit
A34: Less: Outstanding Senior Debt at Exit | B34: 20000000 | D34: Assumed interest-only; principal outstanding at Year 5
A35: Less: Outstanding Mezzanine (PIK accrued 5yr @ 11%) | B35: =B8*(1.11^5) -> 8425290.8 | D35: PIK compounds; no cash pay. $5M grows to ~$8.4M over 5 years at 11%.
A36: Net Equity Proceeds at Exit | B36: =B33-B34-B35 -> 17034180 | D36: Total distributable to equity stack at exit

Sheet Treasury Cashflow
A1: TREASURY MANAGEMENT | Month-by-Month Pre-Opening Cashflow (USD)
A2: LP capital called at Month 0 (August 2026). Treasury yield paid monthly. Capital drawn down into build per 16-month schedule. Opening: Q4 2027.
A4: Month | B4: Opening Balance | C4: Construction Draw | D4: Closing Balance | E4: Treasury Yield (10% p.a.) | F4: APR Paid to LPs | G4: Cumulative APR Paid
A5: Month 01 | B5: ='Fund Assumptions'!B15 -> 7000000 | C5: 262500 | D5: =B5-C5 -> 6737500 | E5: =D5*'Fund Assumptions'!B16/12 -> 56145.833 | F5: =E5 -> 56145.833 | G5: =F5 -> 56145.833
A6: Month 02 | B6: =D5 -> 6737500 | C6: 262500 | D6: =B6-C6 -> 6475000 | E6: =D6*'Fund Assumptions'!B16/12 -> 53958.333 | F6: =E6 -> 53958.333 | G6: =G5+F6 -> 110104.17
A7: Month 03 | B7: =D6 -> 6475000 | C7: 262500 | D7: =B7-C7 -> 6212500 | E7: =D7*'Fund Assumptions'!B16/12 -> 51770.833 | F7: =E7 -> 51770.833 | G7: =G6+F7 -> 161875
A8: Month 04 | B8: =D7 -> 6212500 | C8: 262500 | D8: =B8-C8 -> 5950000 | E8: =D8*'Fund Assumptions'!B16/12 -> 49583.333 | F8: =E8 -> 49583.333 | G8: =G7+F8 -> 211458.33
A9: Month 05 | B9: =D8 -> 5950000 | C9: 437500 | D9: =B9-C9 -> 5512500 | E9: =D9*'Fund Assumptions'!B16/12 -> 45937.5 | F9: =E9 -> 45937.5 | G9: =G8+F9 -> 257395.83
A10: Month 06 | B10: =D9 -> 5512500 | C10: 437500 | D10: =B10-C10 -> 5075000 | E10: =D10*'Fund Assumptions'!B16/12 -> 42291.667 | F10: =E10 -> 42291.667 | G10: =G9+F10 -> 299687.5
A11: Month 07 | B11: =D10 -> 5075000 | C11: 437500 | D11: =B11-C11 -> 4637500 | E11: =D11*'Fund Assumptions'!B16/12 -> 38645.833 | F11: =E11 -> 38645.833 | G11: =G10+F11 -> 338333.33
A12: Month 08 | B12: =D11 -> 4637500 | C12: 437500 | D12: =B12-C12 -> 4200000 | E12: =D12*'Fund Assumptions'!B16/12 -> 35000 | F12: =E12 -> 35000 | G12: =G11+F12 -> 373333.33
A13: Month 09 | B13: =D12 -> 4200000 | C13: 560000 | D13: =B13-C13 -> 3640000 | E13: =D13*'Fund Assumptions'!B16/12 -> 30333.333 | F13: =E13 -> 30333.333 | G13: =G12+F13 -> 403666.67
A14: Month 10 | B14: =D13 -> 3640000 | C14: 560000 | D14: =B14-C14 -> 3080000 | E14: =D14*'Fund Assumptions'!B16/12 -> 25666.667 | F14: =E14 -> 25666.667 | G14: =G13+F14 -> 429333.33
A15: Month 11 | B15: =D14 -> 3080000 | C15: 560000 | D15: =B15-C15 -> 2520000 | E15: =D15*'Fund Assumptions'!B16/12 -> 21000 | F15: =E15 -> 21000 | G15: =G14+F15 -> 450333.33
A16: Month 12 | B16: =D15 -> 2520000 | C16: 560000 | D16: =B16-C16 -> 1960000 | E16: =D16*'Fund Assumptions'!B16/12 -> 16333.333 | F16: =E16 -> 16333.333 | G16: =G15+F16 -> 466666.67
A17: Month 13 | B17: =D16 -> 1960000 | C17: 560000 | D17: =B17-C17 -> 1400000 | E17: =D17*'Fund Assumptions'!B16/12 -> 11666.667 | F17: =E17 -> 11666.667 | G17: =G16+F17 -> 478333.33
A18: Month 14 | B18: =D17 -> 1400000 | C18: 466667 | D18: =B18-C18 -> 933333 | E18: =D18*'Fund Assumptions'!B16/12 -> 7777.775 | F18: =E18 -> 7777.775 | G18: =G17+F18 -> 486111.11
A19: Month 15 | B19: =D18 -> 933333 | C19: 466667 | D19: =B19-C19 -> 466666 | E19: =D19*'Fund Assumptions'!B16/12 -> 3888.8833 | F19: =E19 -> 3888.8833 | G19: =G18+F19 -> 489999.99
A20: Month 16 | B20: =D19 -> 466666 | C20: 466666 | D20: =B20-C20 -> 0 | E20: =D20*'Fund Assumptions'!B16/12 -> 0 | F20: =E20 -> 0 | G20: =G19+F20 -> 489999.99
A21: TOTAL | C21: =SUM(C5:C20) -> 7000000 | E21: =SUM(E5:E20) -> 489999.99 | F21: =SUM(F5:F20) -> 489999.99 | G21: =G20 -> 489999.99
A23: SUMMARY
A24: Total LP Capital Called | B24: ='Fund Assumptions'!B15 -> 7000000
A25: Total Deployed into Construction | B25: =C21 -> 7000000
A26: Total APR Paid to LPs (pre-opening) | B26: =F21 -> 489999.99
A27: Average Monthly APR per LP $1 invested | B27: =IF('Fund Assumptions'!B15<>0,('Fund Assumptions'!B16/12),0) -> 0.0083333333
A28: Note: Treasury yield is earned on closing (undeployed) balance each month. 16-month compressed modular schedule.

Sheet Waterfall Analysis
A1: WATERFALL ANALYSIS | Barbados Single Site | Year 5 Exit (from Opening: Q4 2027)
A2: Four-tier waterfall: Return of Capital > Preferred Return > LP/GP Split > Carried Interest
A4: Waterfall Tier | B4: LP ($) | C4: Coruscant GP ($) | D4: Magnus GP ($) | E4: Notes
A5: TIER 1 — RETURN OF LP CAPITAL
A6: Total Exit Proceeds (net of debt) | B6: ='Fund Assumptions'!B36 -> 17034180 | E6: Gross exit less senior debt and PIK mezzanine
A7: LP Capital Invested | B7: ='Fund Assumptions'!B11 -> 7000000
A8: GP Co-invest Capital (Coruscant) | C8: ='Fund Assumptions'!B10 -> 500000
A9: Tier 1: Return of All Capital (LP + GP) | B9: =B7 -> 7000000 | C9: =C8 -> 500000 | D9: 0 | E9: First dollars out repay all invested capital
A10: Remaining Proceeds after Tier 1 | B10: =B6-B9-C9 -> 9534179.8
A12: TIER 2 — LP PREFERRED RETURN (8% p.a. on invested capital)
A13: LP Preferred Return Required (8% x 5 years x capital) | B13: =B7*'Fund Assumptions'!B23*'Fund Assumptions'!B30 -> 2800000 | E13: Simple preferred return. Compounded version = capital * (1.08^5) - capital
A14: Less: APR Already Paid During Pre-Opening | B14: ='Fund Assumptions'!B20 -> 489999.99 | E14: Treasury yield paid monthly before opening; offsets preferred return owed at exit
A15: Preferred Return Still Owed at Exit | B15: =MAX(0,B13-B14) -> 2310000 | E15: MAX(0) prevents negative; if APR > required, excess goes to Tier 3
A16: Tier 2: Pay Preferred Return Shortfall to LPs | B16: =MIN(B10,B15) -> 2310000 | C16: 0 | D16: 0 | E16: Remaining proceeds satisfy preferred return shortfall first
A17: Remaining Proceeds after Tier 2 | B17: =B10-B16 -> 7224179.8
A19: TIER 3 — DISTRIBUTABLE INCOME SPLIT (70% LP / 30% GP)
A20: Available for Tier 3 Distribution | B20: =B17 -> 7224179.8
A21: LP Share (70% of available) | B21: =B20*'Fund Assumptions'!B24 -> 5056925.9 | C21: 0 | D21: 0
A22: GP Total Carry (30% of available) | B22: 0 | C22: =B20*(1-'Fund Assumptions'!B24)*'Fund Assumptions'!B27 -> 1896347.2 | D22: =B20*(1-'Fund Assumptions'!B24)*'Fund Assumptions'!B26 -> 270906.74 | E22: GP carry split: 87.5% Coruscant, 12.5% Magnus (midpoint of 10-15% stated)
A23: Remaining after Tier 3 | B23: =B20-B21-B22-C22 -> 270906.74
A25: WATERFALL SUMMARY | Total Distributions by Party
A26: Party | B26: Total Received ($) | C26: Multiple on Invested | D26: % of Net Exit | E26: Notes
A27: LP Investors (total) | B27: =B9+B16+B21+B14 -> 14856926 | C27: =IF(B7<>0,B27/B7,0) -> 2.122418 | D27: =IF(B6<>0,B27/B6,0) -> 0.87218322 | E27: Includes APR paid pre-opening plus exit waterfall proceeds
A28: Coruscant GP (total) | B28: =C9+C22 -> 2396347.2 | C28: =IF('Fund Assumptions'!B10<>0,B28/'Fund Assumptions'!B10,0) -> 4.7926944 | D28: =IF(B6<>0,B28/B6,0) -> 0.14067875 | E28: Return of co-invest + 87.5% of 30% GP carry
A29: Magnus Capital (GP fee; 12.5% of carry) | B29: =D22 -> 270906.74 | C29: 0 | D29: =IF(B6<>0,B29/B6,0) -> 0.015903715 | E29: 12.5% of 30% GP carry only; no capital invested
A30: TOTAL CHECK | B30: =B27+B28+B29-B14 -> 17034180 | E30: Should equal Net Equity Proceeds. APR deducted as it was pre-exit cash.
A32: RETURN METRICS SUMMARY
A33: Metric | B33: LP Investors | C33: Coruscant GP | D33: Notes
A34: Total Capital Invested | B34: ='Fund Assumptions'!B11 -> 7000000 | C34: ='Fund Assumptions'!B10 -> 500000
A35: Total Received (incl. APR pre-opening) | B35: =B27 -> 14856926 | C35: =B28 -> 2396347.2
A36: Equity Multiple on Invested Capital | B36: =C27 -> 2.122418 | C36: =C28 -> 4.7926944 | D36: Target: LP 4-6x, Coruscant significantly higher through carry
A37: Share of Total Exit Value | B37: =D27 -> 0.87218322 | C37: =D28 -> 0.14067875
A38: APR Yield Received Pre-Opening (LPs only) | B38: =B14 -> 489999.99 | C38: N/A | D38: LP investors receiving monthly treasury yield from Month 1
A39: Estimated Levered IRR (Year 5 exit) | B39: 17-21% | C39: Higher; GP carry amplifies return on co-invest | D39: Verify with XIRR() once monthly cashflow timing confirmed
A41: SENSITIVITY | LP Multiple vs Exit Cap Rate (Stabilised Year 5 NOI: $3.86M)
A42: Cap Rate / LP Capital | B42: 6.5% | C42: 7.5% | D42: 8.5% | E42: 9.5% | F42: 10.5%
A43: LP $5M | B43: 4.87 | C43: 3.76 | D43: 2.91 | E43: 2.24 | F43: 1.7
A44: LP $6M | B44: 4.14 | C44: 3.22 | D44: 2.51 | E44: 1.95 | F44: 1.5
A45: LP $7M | B45: 3.63 | C45: 2.83 | D45: 2.23 | E45: 1.75 | F45: 1.4
A46: LP $8M | B46: 3.24 | C46: 2.55 | D46: 2.02 | E46: 1.6 | F46: 1.4
...

Sheet Construction Drawdown
A1: CONSTRUCTION DRAWDOWN SCHEDULE | Barbados | 16-Month Build Programme (Aug 2026 – Nov 2027)
A2: Modular prefab programme. LP equity drawn progressively; undeployed balance earns treasury yield. Construction start: August 2026. Opening: Q4 2027.
A5: Phase 1: Design, Planning & Procurement (Months 1-4: Aug 2026 – Nov 2026) — $1,050,000
A6: Activity | B6: Month | C6: Draw (USD) | D6: Cumulative Draw | E6: LP Balance Remaining | F6: Treasury Yield (mo.) | G6: Cumulative APR
A7: Architect retainer + Stage 1a + geotech surveys | B7: Aug 2026 | C7: 262500 | D7: 262500 | E7: 6737500 | F7: 56146 | G7: 56146
A8: EIA screening + structural/MEP concept design | B8: Sep 2026 | C8: 262500 | D8: 525000 | E8: 6475000 | F8: 53958 | G8: 110104
A9: Planning application + module supplier RFI | B9: Oct 2026 | C9: 262500 | D9: 787500 | E9: 6212500 | F9: 51771 | G9: 161875
A10: Procurement finalisation + module PO placed | B10: Nov 2026 | C10: 262500 | D10: 1050000 | E10: 5950000 | F10: 49583 | G10: 211458
A12: Phase 2: Site Prep & Module Fabrication (Months 5-8: Dec 2026 – Mar 2027) — $1,750,000
A13: Activity | B13: Month | C13: Draw (USD) | D13: Cumulative Draw | E13: LP Balance Remaining | F13: Treasury Yield (mo.) | G13: Cumulative APR
A14: Site clearance + excavation + foundation piling | B14: Dec 2026 | C14: 437500 | D14: 1487500 | E14: 5512500 | F14: 45938 | G14: 257396
A15: Foundation pad pour + ground beams | B15: Jan 2027 | C15: 437500 | D15: 1925000 | E15: 5075000 | F15: 42292 | G15: 299688
A16: Structural steel frame erection + slab | B16: Feb 2027 | C16: 437500 | D16: 2362500 | E16: 4637500 | F16: 38646 | G16: 338334
A17: MEP underground + module factory QA inspections | B17: Mar 2027 | C17: 437500 | D17: 2800000 | E17: 4200000 | F17: 35000 | G17: 373334
A19: Phase 3: Module Shipping, Install & MEP (Months 9-13: Apr 2027 – Aug 2027) — $2,800,000
A20: Activity | B20: Month | C20: Draw (USD) | D20: Cumulative Draw | E20: LP Balance Remaining | F20: Treasury Yield (mo.) | G20: Cumulative APR
A21: Module shipping (65 containers) + crane mobilisation | B21: Apr 2027 | C21: 560000 | D21: 3360000 | E21: 3640000 | F21: 30333 | G21: 403667
A22: Crane lift YOTEL modules Floors 1-3 | B22: May 2027 | C22: 560000 | D22: 3920000 | E22: 3080000 | F22: 25667 | G22: 429334
A23: Crane lift YOTELPAD modules Floors 4-5 | B23: Jun 2027 | C23: 560000 | D23: 4480000 | E23: 2520000 | F23: 21000 | G23: 450334
A24: MEP connections at module interfaces + cladding | B24: Jul 2027 | C24: 560000 | D24: 5040000 | E24: 1960000 | F24: 16333 | G24: 466667
A25: External weather envelope + elevator core | B25: Aug 2027 | C25: 560000 | D25: 5600000 | E25: 1400000 | F25: 11667 | G25: 478334
A27: Phase 4: Fit-Out, Commissioning & Pre-Open (Months 14-16: Sep 2027 – Nov 2027) — $1,400,000
A28: Activity | B28: Month | C28: Draw (USD) | D28: Cumulative Draw | E28: LP Balance Remaining | F28: Treasury Yield (mo.) | G28: Cumulative APR
A29: FF&E installation + tech stack / YOTEL PMS setup | B29: Sep 2027 | C29: 466667 | D29: 6066667 | E29: 933333 | F29: 7778 | G29: 486112
A30: YOTEL brand inspection + snagging + pre-opening staff | B30: Oct 2027 | C30: 466667 | D30: 6533334 | E30: 466666 | F30: 3889 | G30: 490001
A31: Soft open → full brand launch Q4 2027 | B31: Nov 2027 | C31: 466666 | D31: 7000000 | E31: 0 | F31: 0 | G31: 490001
A33: DRAWDOWN SUMMARY
A34: Total LP Equity Deployed into Construction | C34: 7000000
A35: Total Treasury Yield Generated (pre-opening) | F35: 490001
A36: Yield declines each month as capital is drawn from custodial account into the build. Compressed 16-month modular schedule reduces total yield vs 24-month programme.
