Workbook

Sheet Pre-Dev Budget
A1: YOTEL + YOTELPAD BARBADOS | PRE-DEVELOPMENT FUNDING REQUEST | Coruscant Developments Ltd.
A2: Funding Provider: Magnus Capital | Period: April 2026 through July 2026 (4 months) | Confidential
A4: PURPOSE & SCOPE
A5: This budget covers the pre-development phase from financial close (April 2026) through submission of the full planning application and EIA screening (July 2026). It funds the work required to take the project from current concept stage to a planning-ready position: master planning, architect Stage 1a/1b, structural and MEP concept, geotechnical survey, EIA screening, legal, YOTEL brand engagement, and Coruscant project management. All costs are in USD. Barbados dollar amounts converted at BD$2.00 : USD$1.00.
A7: Cost Item | B7: Apr 2026 | C7: May 2026 | D7: Jun 2026 | E7: Jul 2026 | F7: Total (USD) | G7: Basis / Source
A8: PROFESSIONAL FEES
A9: Architect: Stage 1a Retainer (10% of fee) | B9: 137000 | C9: 0 | D9: 0 | E9: 0 | F9: =SUM(B9:E9) -> 137000 | G9: BD$321,750 net of 17.5% VAT = USD$137,000. Payable on contract execution. Source: Architect fee letter Feb 2026 (5.5% of BD$58.5M construction cost).
A10: Architect: Stage 1b Concept Design (15% of fee) | B10: 0 | C10: 68000 | D10: 68000 | E10: 69000 | F10: =SUM(B10:E10) -> 205000 | G10: BD$482,625 net VAT = USD$205,000. Spread across months 2-4. Covers concept design, massing, room count confirmation, YOTEL brand submission package.
A11: Structural Engineer: Concept Stage | B11: 0 | C11: 15000 | D11: 15000 | E11: 20000 | F11: =SUM(B11:E11) -> 50000 | G11: USD$50,000 for structural strategy, foundation concept, hurricane load review. Source: Project budget assumption; consistent with BCQS 2025 soft cost benchmarks for a 130-key hotel.
A12: MEP Engineer: Concept Stage | B12: 0 | C12: 12000 | D12: 13000 | E12: 0 | F12: =SUM(B12:E12) -> 25000 | G12: USD$25,000 for MEP concept: electrical, plumbing, HVAC strategy for modular interface. Paid in months 2-3.
A13: Quantity Surveyor: Preliminary Cost Plan | B13: 0 | C13: 0 | D13: 7500 | E13: 7500 | F13: =SUM(B13:E13) -> 15000 | G13: USD$15,000 for elemental cost plan to accompany planning submission. Source: Project budget; QS fee confirmed in soft cost schedule.
A14: YOTEL Technical Services: Stage 1 Engagement Fee | B14: 5000 | C14: 5000 | D14: 5000 | E14: 5000 | F14: =SUM(B14:E14) -> 20000 | G14: USD$5,000/month retainer for YOTEL TSA engagement during concept and design review phase. Source: YOTEL Feasibility Guidelines Total phase cost USD$20,000 (est.).
A15: SURVEYS AND SITE INVESTIGATIONS
A16: Geotechnical Survey and Report | B16: 17000 | C16: 0 | D16: 0 | E16: 0 | F16: =SUM(B16:E16) -> 17000 | G16: USD$17,000 for borehole programme, limestone bedrock assessment, and geotechnical report. Source: Project budget assumption. Limestone bedrock condition may reduce cost vs piling sites.
A17: Boundary Survey and Site Measured Drawing | B17: 10000 | C17: 0 | D17: 0 | E17: 0 | F17: =SUM(B17:E17) -> 10000 | G17: USD$10,000 for re-survey of the irregular polygon site at Bay Street. Confirms 27m frontage, total site area, and cadastral boundaries for planning drawings.
A18: Topographical and Drainage Survey | B18: 0 | C18: 5000 | D18: 0 | E18: 0 | F18: =SUM(B18:E18) -> 5000 | G18: USD$5,000 for topo survey and drainage catchment assessment required for EIA screening. Required under Planning and Development (EIA) Regulations 2021.
A19: REGULATORY, PLANNING AND LEGAL
A20: Planning: Pre-Application Consultation Fee (Barbados) | B20: 0 | C20: 3500 | D20: 0 | E20: 0 | F20: =SUM(B20:E20) -> 3500 | G20: Prescribed fee payable to Barbados Town and Country Planning Department on booking pre-application consultation. Source: Planning and Development Act 2019 and EIA Regulations 2021.
A21: EIA Screening Report (Environmental Consultant) | B21: 0 | C21: 0 | D21: 18000 | E21: 12000 | F21: =SUM(B21:E21) -> 30000 | G21: USD$30,000 for EIA screening report and scoping submission. Required for hotel development under Planning and Development (EIA) Regulations 2021, Gazette No. 89 December 2021. Split months 3-4.
A22: Legal: Title, Development Agreement, Contract Review | B22: 8000 | C22: 5000 | D22: 5000 | E22: 5000 | F22: =SUM(B22:E22) -> 23000 | G22: USD$23,000 for local Barbados counsel: title due diligence, option or purchase agreement review, franchise agreement heads of terms review, and planning application legal support.
A23: YOTEL Franchise Agreement: Legal (Heads of Terms) | B23: 0 | C23: 7500 | D23: 7500 | E23: 0 | F23: =SUM(B23:E23) -> 15000 | G23: USD$15,000 for specialist hospitality legal counsel to review YOTEL franchise heads of terms. Separate from local planning legal. UK-based counsel familiar with YOTEL agreements.
A24: PROJECT MANAGEMENT AND CORUSCANT OPERATING COSTS
A25: Coruscant: Developer Management Fee | B25: 15000 | C25: 15000 | D25: 15000 | E25: 15000 | F25: =SUM(B25:E25) -> 60000 | G25: USD$15,000/month. $32.5M branded hotel project during pre-development. Full scope hotel fee development: 3-5% of total cost .
A26: Project Administration and Office Costs | B26: 2500 | C26: 2500 | D26: 2500 | E26: 2500 | F26: =SUM(B26:E26) -> 10000 | G26: USD$2,500/month. courier, printing, planning document production, YOTEL submission costs, and project administration.
A27: Travel and Stakeholder Meetings | B27: 3500 | C27: 3500 | D27: 3500 | E27: 3500 | F27: =SUM(B27:E27) -> 14000 | G27: USD$3,500/month average. Flights and accommodation for Coruscant team, investor meetings, YOTEL CEO meetings, government agency pre-application consultations, and site visits.
A28: CONTINGENCY
A29: Pre-Development Contingency (10%) | B29: =ROUND(SUM(B9:B28)*0.1,0) -> 19800 | C29: =ROUND(SUM(C9:C28)*0.1,0) -> 14200 | D29: =ROUND(SUM(D9:D28)*0.1,0) -> 16000 | E29: =ROUND(SUM(E9:E28)*0.1,0) -> 13950 | F29: =SUM(B29:E29) -> 63950 | G29: 10% contingency on total professional and survey costs. Standard pre-development contingency to cover scope additions, additional consultant meetings, and unforeseen regulatory requirements.
A31: MONTHLY TOTAL EXPENDITURE | B31: =SUM(B9:B29) -> 217800 | C31: =SUM(C9:C29) -> 156200 | D31: =SUM(D9:D29) -> 176000 | E31: =SUM(E9:E29) -> 153450 | F31: =SUM(F9:F29) -> 703450
A32: CUMULATIVE BURN (running total) | B32: =B31 -> 217800 | C32: =B32+C31 -> 374000 | D32: =C32+D31 -> 550000 | E32: =D32+E31 -> 703450 | F32: =F31 -> 703450
A33: FUND BALANCE REMAINING (Magnus Facility less cumulative burn) | B33: =Assumptions!B4-B32 -> 182200 | C33: =Assumptions!B4-C32 -> 26000 | D33: =Assumptions!B4-D32 -> -150000 | E33: =Assumptions!B4-E32 -> -303450 | F33: =Assumptions!B4-F31 -> -303450
A35: FUNDING REQUEST SUMMARY
A36: Magnus Capital Pre-Development Facility (requested) | C36: =Assumptions!B3 -> 0
A37: Total Pre-Development Spend (4 months, incl. contingency) | C37: =F31 -> 703450
A38: Unallocated Reserve at Period End | C38: =Assumptions!B3-F31 -> -703450
A39: Monthly Average Burn Rate | C39: =F31/4 -> 175862.5
A40: Coruscant Developer Management Fee (total 4 months) | C40: =F25 -> 60000
A41: Management Fee as % of Facility | C41: =F25/F31 -> 0.085293909
A43: FEE JUSTIFICATION | Developer Management Fee
A44: The Coruscant Developer Management Fee of USD$15,000 per month is set at the lower end of published industry norms for a project of this size and complexity. Full-scope fee developer: 3-8% of total project cost. For a USD$32.5M hotel: 3% = USD$975,000 lifecycle fee; 5% = USD$1,625,000. Pre-development portion (approx. 10-15% of lifecycle): USD$97,500 - USD$243,750. USD$15,000/month x 4 months = USD$60,000 = 6.2% of pre-dev budget; 0.18% of total project cost. This fee covers: daily project direction and decision-making, brand liaison with YOTEL, coordination of all professional consultants, stakeholder and investor management, regulatory strategy, and management of the pre-development programme. The fee does not cover out-of-pocket expenses, which are separately budgeted under Project Administration and Travel.
A46: DRAWDOWN TRIGGERS | Capital Release Conditions
...

Sheet Assumptions
A1: ASSUMPTIONS | Pre-Development Funding Request
A3: FUNDING ASSUMPTIONS
A4: Magnus Capital Pre-Development Facility (USD) | B4: 400000 | C4: Requested amount. Phil suggested USD$500K; Kevyn estimated USD$300K. USD$400K midpoint request covers full 4-month programme with 10% contingency and unallocated reserve.
A5: Facility Period (months) | B5: 4 | C5: April 2026 through July 2026 inclusive.
A6: BD$ : USD Exchange Rate | B6: 2 | C6: Fixed peg. Barbados dollar pegged to USD at 2:1 since 1975.
A7: Architect Fee Basis (BD$, incl. VAT) | B7: 3217500 | C7: 5.5% of BD$58.5M construction cost = BD$3,217,500. VAT at 17.5% included. Source: Architect fee letter February 2026.
A8: Developer Management Fee per Month (USD) | B8: 15000 | C8: Industry standard for pre-development management on a USD$32.5M branded hotel. Lower end of 3-5% lifecycle fee developer benchmark.
A9: Contingency Rate on Professional and Survey Costs | B9: 0.1 | C9: 10% pre-development contingency. Standard industry allowance for scope additions, additional meetings, and unforeseen regulatory requirements.

Sheet Programme Timeline
A1: PRE-DEVELOPMENT PROGRAMME TIMELINE | April through July 2026
A2: Activity sequence from financial close through planning application submission. Parallel workstreams shown.
A4: Workstream / Activity | B4: Apr 2026 | C4: May 2026 | D4: Jun 2026 | E4: Jul 2026 | F4: Output / Milestone
A5: DESIGN AND ARCHITECTURE
A6: Contract execution and architect retainer payment | B6: • | F6: Stage 1a fee paid; design brief confirmed
A7: Concept design: massing, floor plans, room count | B7: • | C7: • | F7: Concept design package
A8: YOTEL brand submission package | C8: • | D8: • | F8: Formal YOTEL feasibility submission
A9: Stage 1b: design development, area schedule | C9: • | D9: • | E9: • | F9: Stage 1b complete; YOTEL comment received
A10: Structural and MEP concept design | C10: • | D10: • | F10: Structural and MEP concept report
A11: Preliminary cost plan (QS) | D11: • | E11: • | F11: Elemental cost plan for planning submission
A12: SURVEYS AND INVESTIGATIONS
A13: Geotechnical survey and report | B13: • | C13: • | F13: Geotech report confirming limestone bedrock
A14: Boundary and topographical survey | B14: • | F14: Survey drawings for planning
A15: Drainage and catchment assessment | C15: • | F15: Drainage report for EIA screening
A16: REGULATORY AND PLANNING
A17: Pre-application consultation: book appointment | B17: • | F17: Appointment booked with TCPD
A18: Pre-application meeting with planning department | C18: • | F18: Pre-app meeting notes; required documents list
A19: EIA screening instruction to environmental consultant | C19: • | F19: EIA consultant instructed
A20: EIA screening report prepared | D20: • | E20: • | F20: EIA screening report complete
A21: EIA screening submission to planning | E21: • | F21: EIA screening submitted
A22: Planning application drawing package | D22: • | E22: • | F22: Planning drawings and design statement
A23: Planning application submission | E23: • | F23: Full planning application lodged
A24: LEGAL AND COMMERCIAL
A25: Site legal due diligence | B25: • | C25: • | F25: Title confirmed; encumbrances identified
A26: Option or purchase agreement negotiation | C26: • | D26: • | F26: Heads of terms or agreement exchanged
A27: YOTEL franchise heads of terms review | C27: • | D27: • | F27: YOTEL HoT agreed or progressed
A28: Magnus Capital funding agreement execution | B28: • | F28: Facility agreement signed; funds released
A29: PROJECT MANAGEMENT
A30: Coruscant: programme management and coordination | B30: • | C30: • | D30: • | E30: • | F30: Monthly progress reports to Magnus
A31: Investor stakeholder updates | B31: • | C31: • | D31: • | E31: • | F31: Monthly reporting and calls
A32: YOTEL CEO engagement and investor introductions | C32: • | D32: • | E32: • | F32: Investor conversations progressed
A34: KEY MILESTONES AND DECISION POINTS
A35: Milestone | B35: Target Date | C35: Dependency | D35: Decision / Output
A36: Magnus pre-development facility signed | B36: 30 Mar 2026 | C36: Coruscant entity and NDA confirmed | D36: Funds released; all consultants instructed
A37: Architect Stage 1a retainer paid | B37: 30 Mar 2026 | C37: Magnus facility live | D37: Design programme starts
A38: Geotechnical mobilisation | B38: 01 Apr 2026 | C38: Survey contract signed | D38: Rig on site within 2 weeks
A39: Pre-application meeting booked | B39: 14 Apr 2026 | C39: Application form and fee submitted to TCPD | D39: Pre-app slot confirmed
A40: Architect Stage 1b commenced | B40: 01 May 2026 | C40: Stage 1a retainer complete | D40: Design development underway
A41: Pre-application consultation held | B41: 15 May 2026 | C41: Planning dept. appointment | D41: Required documents list for full submission
A42: EIA screening instruction issued | B42: 15 May 2026 | C42: Drainage survey complete | D42: Environmental consultant on programme
...
