Workbook

Sheet Assumptions
A1: MOUNT BREVITOR ESTATE DEVELOPMENT
A2: Financial Model Assumptions Sheet | v2.0 | March 2025
A3: Blue = Input | Black = Formula | Green = Cross-sheet link | Yellow = Key assumption
A5: SITE PARAMETERS
A6: Total Site Area (acres) | B6: 120 | G6: Confirmed
A7: Residential Area (acres, est.) | B7: 55 | G7: Developer estimate, subject to master plan
A8: Farm Area (acres, est.) | B8: 25 | G8: Includes aquaponics, pasture, veg
A9: Golf / X Range Area (acres, est.) | B9: 6 | G9: Agricultural land, conversion required
A10: Infrastructure / Common (acres, est.) | B10: 20 | G10: Roads, utilities, amenities
A11: Green / Buffer (acres, est.) | B11: 14 | G11: Parks, setbacks, environmental
A13: CURRENCY
A14: BBD:USD Exchange Rate | B14: 2 | G14: Fixed peg since 1975
A15: Primary Currency | B15: BBD
A17: UNIT MIX AND PRICING
A18: Unit Type | B18: Units | C18: Avg Size (sq ft) | D18: Price BBD | E18: Price USD | F18: GDV BBD | G18: Source / Note
A19: 1-Bed Condo | B19: 80 | C19: 750 | D19: 440000 | E19: =D19/B14 | F19: =B19*D19 | G19: Entry product, local buyers
A20: 2-Bed Townhouse | B20: 95 | C20: 1100 | D20: 560000 | E20: =D20/B14 | F20: =B20*D20 | G20: Core mid-market product
A21: 3-Bed Townhouse | B21: 85 | C21: 1450 | D21: 623700 | E21: =D21/B14 | F21: =B21*D21 | G21: Upgrader / diaspora
A22: 4-Bed Home | B22: 55 | C22: 2000 | D22: 880000 | E22: =D22/B14 | F22: =B22*D22 | G22: Upper-tier, demand unverified
A23: 5-Bed Estate Home | B23: 40 | C23: 2800 | D23: 1430000 | E23: =D23/B14 | F23: =B23*D23 | G23: Luxury, requires market validation
A24: TOTAL RESIDENTIAL | B24: =SUM(B19:B23) | E24: =F24/B14 | F24: =SUM(F19:F23)
A26: CONSTRUCTION COST ASSUMPTIONS
A27: BCQS 2025 Benchmark (BBD/sq ft, modest) | B27: 275 | G27: Source: BCQS Caribbean Construction Report 2025
A28: BCQS 2025 Benchmark (BBD/sq ft, mid-range) | B28: 350 | G28: Source: BCQS 2025. Mid-range residential.
A29: BCQS 2025 Benchmark (BBD/sq ft, upper) | B29: 450 | G29: Source: BCQS 2025. Upper residential / finishing.
A30: Developer Claimed Savings (%) | B30: 0.25 | G30: 20-30% claimed. NOT independently verified. FLAG.
A31: Cost Escalation Rate (annual) | B31: 0.043 | G31: Source: BCQS 2025 trend data (4.3% p.a.)
A32: Site Preparation (BBD/acre) | B32: 40000 | G32: Estimated. Geotechnical survey outstanding.
A33: Infrastructure Cost (BBD, total est.) | B33: 18000000 | G33: Roads, water, sewage, electrical. Developer est.
A35: FINANCING ASSUMPTIONS
A36: Loan Facility (USD) | B36: 57000000 | G36: Developer stated. Strategic partner facility.
A37: Interest Rate (stated) | B37: 0.05 | G37: FLAG: Below Barbados commercial rates (6-9%). See F-01.
A38: Interest Rate (market benchmark) | B38: 0.075 | G38: Mid-point of 6-9% Barbados commercial range.
A39: Loan Term (years) | B39: 4 | G39: 2025-2028 per developer draw schedule.
A40: Pre-Sales Threshold (%) | B40: 0.1 | G40: Developer assumption. Industry norm: 20-30%. FLAG.
A41: Land Cost (USD) | B41: 4500000 | G41: Confirmed per draw schedule.
A42: Contingency (%) | B42: 0.1 | G42: Advisory recommendation: minimum 10%.
A44: ABSORPTION ASSUMPTIONS
A45: Base Case Absorption (units/year) | B45: 110 | G45: Mid-point of 100-120 range. B1 Demand Analysis.
A46: Conservative Absorption (units/year) | B46: 70 | G46: Mid-point of 60-80 range.
...

Sheet Revenue Model
A1: MOUNT BREVITOR ESTATE DEVELOPMENT
A2: Revenue Model | BBD Primary | v2.0
A4: Revenue Line | B4: Unit | C4: 2025 | D4: 2026 | E4: 2027 | F4: 2028 | G4: Total
A5: RESIDENTIAL REVENUE (BBD)
A6: 1-Bed Condo Sales | B6: Units | C6: 10 | D6: 30 | E6: 25 | F6: 15 | G6: =SUM(C6:F6)
A7: 2-Bed Townhouse Sales | B7: Units | C7: 8 | D7: 35 | E7: 32 | F7: 20 | G7: =SUM(C7:F7)
A8: 3-Bed Townhouse Sales | B8: Units | C8: 7 | D8: 30 | E8: 28 | F8: 20 | G8: =SUM(C8:F8)
A9: 4-Bed Home Sales | B9: Units | C9: 3 | D9: 15 | E9: 20 | F9: 17 | G9: =SUM(C9:F9)
A10: 5-Bed Estate Home Sales | B10: Units | C10: 2 | D10: 10 | E10: 10 | F10: 18 | G10: =SUM(C10:F10)
A11: Total Units Sold | B11: Units | C11: =SUM(C6:C10) | D11: =SUM(D6:D10) | E11: =SUM(E6:E10) | F11: =SUM(F6:F10) | G11: =SUM(C11:F11)
A13: RESIDENTIAL REVENUE BY TYPE (BBD)
A14: 1-Bed Condo Revenue | B14: BBD | C14: =C6*Assumptions!D19 | D14: =D6*Assumptions!D19 | E14: =E6*Assumptions!D19 | F14: =F6*Assumptions!D19 | G14: =SUM(C14:F14)
A15: 2-Bed Townhouse Revenue | B15: BBD | C15: =C7*Assumptions!D20 | D15: =D7*Assumptions!D20 | E15: =E7*Assumptions!D20 | F15: =F7*Assumptions!D20 | G15: =SUM(C15:F15)
A16: 3-Bed Townhouse Revenue | B16: BBD | C16: =C8*Assumptions!D21 | D16: =D8*Assumptions!D21 | E16: =E8*Assumptions!D21 | F16: =F8*Assumptions!D21 | G16: =SUM(C16:F16)
A17: 4-Bed Home Revenue | B17: BBD | C17: =C9*Assumptions!D22 | D17: =D9*Assumptions!D22 | E17: =E9*Assumptions!D22 | F17: =F9*Assumptions!D22 | G17: =SUM(C17:F17)
A18: 5-Bed Estate Home Revenue | B18: BBD | C18: =C10*Assumptions!D23 | D18: =D10*Assumptions!D23 | E18: =E10*Assumptions!D23 | F18: =F10*Assumptions!D23 | G18: =SUM(C18:F18)
A19: TOTAL RESIDENTIAL REVENUE (BBD) | B19: BBD | C19: =SUM(C14:C18) | D19: =SUM(D14:D18) | E19: =SUM(E14:E18) | F19: =SUM(F14:F18) | G19: =SUM(G14:G18)
A20: TOTAL RESIDENTIAL REVENUE (USD) | B20: USD | C20: =C19/Assumptions!B14 | D20: =D19/Assumptions!B14 | E20: =E19/Assumptions!B14 | F20: =F19/Assumptions!B14 | G20: =G19/Assumptions!B14
A22: NON-RESIDENTIAL REVENUE (BBD)
A23: Farm Revenue (BBD) | B23: BBD | C23: 0 | D23: 500000 | E23: 2000000 | F23: 3000000 | G23: =SUM(C23:F23)
A24: X Range / Golf Revenue (BBD) | B24: BBD | C24: 0 | D24: 0 | E24: 3000000 | F24: 5000000 | G24: =SUM(C24:F24)
A25: Lot Premium / Amenity Fees (BBD) | B25: BBD | C25: 200000 | D25: 600000 | E25: 800000 | F25: 400000 | G25: =SUM(C25:F25)
A26: Commercial Lease Revenue (BBD) | B26: BBD | C26: 0 | D26: 0 | E26: 500000 | F26: 1500000 | G26: =SUM(C26:F26)
A27: Solar Energy Revenue (BBD) | B27: BBD | C27: 0 | D27: 0 | E27: 300000 | F27: 600000 | G27: =SUM(C27:F27)
A28: TOTAL NON-RESIDENTIAL REVENUE (BBD) | B28: BBD | C28: =SUM(C23:C27) | D28: =SUM(D23:D27) | E28: =SUM(E23:E27) | F28: =SUM(F23:F27) | G28: =SUM(G23:G27)
A30: TOTAL PROJECT REVENUE
A31: GROSS DEVELOPMENT VALUE (BBD) | B31: BBD | C31: =C19+C28 | D31: =D19+D28 | E31: =E19+E28 | F31: =F19+F28 | G31: =G19+G28
A32: GROSS DEVELOPMENT VALUE (USD) | B32: USD | C32: =C31/Assumptions!B14 | D32: =D31/Assumptions!B14 | E32: =E31/Assumptions!B14 | F32: =F31/Assumptions!B14 | G32: =G31/Assumptions!B14

Sheet Cost Model
A1: MOUNT BREVITOR ESTATE DEVELOPMENT
A2: Cost Model | BBD Primary | Base Case: BCQS 2025 Benchmark | v2.0
A4: Cost Line | B4: Unit | C4: 2025 | D4: 2026 | E4: 2027 | F4: 2028 | G4: Total
A5: LAND ACQUISITION (BBD)
A6: Land Purchase | B6: BBD | C6: 9000000 | D6: 0 | E6: 0 | F6: 0 | G6: =SUM(C6:F6)
A7: Stamp Duty and Legal | B7: BBD | C7: 450000 | D7: 0 | E7: 0 | F7: 0 | G7: =SUM(C7:F7)
A8: Total Land Cost | C8: =SUM(C6:C7) | D8: =SUM(D6:D7) | E8: =SUM(E6:E7) | F8: =SUM(F6:F7) | G8: =SUM(G6:G7)
A10: CONSTRUCTION COSTS - BASE CASE (BBD) | G10: BCQS 2025 benchmark rates, NO developer savings
A11: 1-Bed Condo Construction | B11: 206250 | C11: ='Revenue Model'!C6*B11 | D11: ='Revenue Model'!D6*B11 | E11: ='Revenue Model'!E6*B11 | F11: ='Revenue Model'!F6*B11 | G11: =SUM(C11:F11)
A12: 2-Bed Townhouse Construction | B12: 330000 | C12: ='Revenue Model'!C7*B12 | D12: ='Revenue Model'!D7*B12 | E12: ='Revenue Model'!E7*B12 | F12: ='Revenue Model'!F7*B12 | G12: =SUM(C12:F12)
A13: 3-Bed Townhouse Construction | B13: 507500 | C13: ='Revenue Model'!C8*B13 | D13: ='Revenue Model'!D8*B13 | E13: ='Revenue Model'!E8*B13 | F13: ='Revenue Model'!F8*B13 | G13: =SUM(C13:F13)
A14: 4-Bed Home Construction | B14: 800000 | C14: ='Revenue Model'!C9*B14 | D14: ='Revenue Model'!D9*B14 | E14: ='Revenue Model'!E9*B14 | F14: ='Revenue Model'!F9*B14 | G14: =SUM(C14:F14)
A15: 5-Bed Estate Home Construction | B15: 1260000 | C15: ='Revenue Model'!C10*B15 | D15: ='Revenue Model'!D10*B15 | E15: ='Revenue Model'!E10*B15 | F15: ='Revenue Model'!F10*B15 | G15: =SUM(C15:F15)
A16: Total Construction Cost (Base) | C16: =SUM(C11:C15) | D16: =SUM(D11:D15) | E16: =SUM(E11:E15) | F16: =SUM(F11:F15) | G16: =SUM(G11:G15)
A18: INFRASTRUCTURE AND SITE WORKS (BBD)
A19: Site Preparation (120 acres) | B19: BBD | C19: 2400000 | D19: 2400000 | E19: 0 | F19: 0 | G19: =SUM(C19:F19)
A20: Roads and Access | B20: BBD | C20: 1000000 | D20: 3000000 | E20: 2000000 | F20: 0 | G20: =SUM(C20:F20)
A21: Water Treatment Plant | B21: BBD | C21: 0 | D21: 5000000 | E21: 1000000 | F21: 0 | G21: =SUM(C21:F21)
A22: Sewage System | B22: BBD | C22: 0 | D22: 4000000 | E22: 1000000 | F22: 0 | G22: =SUM(C22:F22)
A23: Electrical and Solar | B23: BBD | C23: 500000 | D23: 2000000 | E23: 2000000 | F23: 1000000 | G23: =SUM(C23:F23)
A24: Community Amenities | B24: BBD | C24: 0 | D24: 1000000 | E24: 3000000 | F24: 2000000 | G24: =SUM(C24:F24)
A25: Total Infrastructure | C25: =SUM(C19:C24) | D25: =SUM(D19:D24) | E25: =SUM(E19:E24) | F25: =SUM(F19:F24) | G25: =SUM(G19:G24)
A27: PROFESSIONAL FEES AND SOFT COSTS (BBD)
A28: Architectural and Design | B28: BBD | C28: 2000000 | D28: 1000000 | E28: 500000 | F28: 0 | G28: =SUM(C28:F28)
A29: Engineering and Surveys | B29: BBD | C29: 800000 | D29: 400000 | E29: 200000 | F29: 0 | G29: =SUM(C29:F29)
A30: Legal and Planning | B30: BBD | C30: 600000 | D30: 300000 | E30: 200000 | F30: 100000 | G30: =SUM(C30:F30)
A31: Marketing and Sales | B31: BBD | C31: 1500000 | D31: 3000000 | E31: 2500000 | F31: 1500000 | G31: =SUM(C31:F31)
A32: Project Management | B32: BBD | C32: 800000 | D32: 1200000 | E32: 1000000 | F32: 600000 | G32: =SUM(C32:F32)
A33: Insurance | B33: BBD | C33: 300000 | D33: 600000 | E33: 600000 | F33: 400000 | G33: =SUM(C33:F33)
A34: Contingency (10%) | B34: BBD | C34: =(C16+C25)*Assumptions!B42 | D34: =(D16+D25)*Assumptions!B42 | E34: =(E16+E25)*Assumptions!B42 | F34: =(F16+F25)*Assumptions!B42 | G34: =SUM(C34:F34)
A35: Total Soft Costs | C35: =SUM(C28:C34) | D35: =SUM(D28:D34) | E35: =SUM(E28:E34) | F35: =SUM(F28:F34) | G35: =SUM(G28:G34)
A37: FINANCING COSTS (BBD)
A38: Interest on Facility (at stated 5%) | B38: BBD | C38: 375000 | D38: 2705000 | E38: 5060000 | F38: 5585000 | G38: =SUM(C38:F38)
A39: Interest on Facility (at market 7.5%) | B39: BBD | C39: 562500 | D39: 4057500 | E39: 7590000 | F39: 8377500 | G39: =SUM(C39:F39)
A40: Loan Arrangement Fee (est. 1%) | B40: BBD | C40: 1140000 | D40: 0 | E40: 0 | F40: 0 | G40: =SUM(C40:F40)
A41: Total Financing Cost (at 5%) | C41: =C38+C40 | D41: =D38+D40 | E41: =E38+E40 | F41: =F38+F40 | G41: =G38+G40
A43: TOTAL DEVELOPMENT COST SUMMARY (BBD)
A44: Land Acquisition | C44: =C8 | D44: =D8 | E44: =E8 | F44: =F8 | G44: =G8
A45: Construction (Base Case) | C45: =C16 | D45: =D16 | E45: =E16 | F45: =F16 | G45: =G16
A46: Infrastructure | C46: =C25 | D46: =D25 | E46: =E25 | F46: =F25 | G46: =G25
...

Sheet Cash Flow
A1: MOUNT BREVITOR ESTATE DEVELOPMENT
A2: Phased Cash Flow Model | BBD | v2.0
A4: Cash Flow Item | B4: Unit | C4: 2025 | D4: 2026 | E4: 2027 | F4: 2028 | G4: Total
A5: CASH INFLOWS (BBD)
A6: Residential Sales Revenue | B6: BBD | C6: ='Revenue Model'!C19 | D6: ='Revenue Model'!D19 | E6: ='Revenue Model'!E19 | F6: ='Revenue Model'!F19 | G6: =SUM(C6:F6)
A7: Non-Residential Revenue | B7: BBD | C7: ='Revenue Model'!C28 | D7: ='Revenue Model'!D28 | E7: ='Revenue Model'!E28 | F7: ='Revenue Model'!F28 | G7: =SUM(C7:F7)
A8: Loan Facility Draws | B8: BBD | C8: 15000000 | D8: 78200000 | E8: 16000000 | F8: 5000000 | G8: =SUM(C8:F8)
A9: TOTAL CASH INFLOWS | C9: =C6+C7+C8 | D9: =D6+D7+D8 | E9: =E6+E7+E8 | F9: =F6+F7+F8 | G9: =G6+G7+G8
A11: CASH OUTFLOWS (BBD)
A12: Total Development Cost | B12: BBD | C12: ='Cost Model'!C49 | D12: ='Cost Model'!D49 | E12: ='Cost Model'!E49 | F12: ='Cost Model'!F49 | G12: =SUM(C12:F12)
A13: Loan Repayments | B13: BBD | C13: 0 | D13: 0 | E13: 20000000 | F13: 94200000 | G13: =SUM(C13:F13)
A14: TOTAL CASH OUTFLOWS | C14: =C12+C13 | D14: =D12+D13 | E14: =E12+E13 | F14: =F12+F13 | G14: =G12+G13
A16: NET CASH POSITION
A17: Net Cash Flow (Annual) | B17: BBD | C17: =C9-C14 | D17: =D9-D14 | E17: =E9-E14 | F17: =F9-F14 | G17: =G9-G14
A18: Cumulative Cash Position | B18: BBD | C18: =C17 | D18: =C18+D17 | E18: =D18+E17 | F18: =E18+F17 | G18: =F18
A20: Peak Negative Cash Position | C20: =MIN(C18:F18)

Sheet Development Appraisal
A1: MOUNT BREVITOR ESTATE DEVELOPMENT
A2: Consolidated Development Appraisal | v2.0
A4: Metric | B4: BBD | C4: USD | D4: % of GDV | E4: Notes
A5: Gross Development Value | B5: ='Revenue Model'!G31 | C5: =B5/Assumptions!B14 | D5: 1 | E5: Residential + non-residential
A6: Land Acquisition | B6: ='Cost Model'!G8 | C6: =B6/Assumptions!B14 | D6: =B6/B5 | E6: Confirmed USD 4.5M
A7: Construction (Base Case) | B7: ='Cost Model'!G16 | C7: =B7/Assumptions!B14 | D7: =B7/B5 | E7: BCQS 2025 rates
A8: Infrastructure | B8: ='Cost Model'!G25 | C8: =B8/Assumptions!B14 | D8: =B8/B5 | E8: Roads, water, sewage, power
A9: Professional Fees and Soft Costs | B9: ='Cost Model'!G35 | C9: =B9/Assumptions!B14 | D9: =B9/B5 | E9: Incl. 10% contingency
A10: Financing (at 5%) | B10: ='Cost Model'!G41 | C10: =B10/Assumptions!B14 | D10: =B10/B5 | E10: FLAG: 5% below market
A11: TOTAL DEVELOPMENT COST | B11: =SUM(B6:B10) | C11: =B11/Assumptions!B14 | D11: =B11/B5
A12: NET DEVELOPMENT PROFIT | B12: =B5-B11 | C12: =B12/Assumptions!B14 | D12: =B12/B5
A14: KEY RETURN METRICS
A15: Profit on GDV (%) | B15: =B12/B5 | E15: Target: 20%+ for institutional grade
A16: Profit on Cost (%) | B16: =B12/B11 | E16: Target: 25%+ for risk-adjusted return
A17: GDV per Acre (BBD) | B17: =B5/Assumptions!B6 | E17: 120 acres
A18: Cost per Unit (BBD, avg) | B18: =B11/Assumptions!F24 | E18: Total cost / total units
A19: Revenue per Unit (BBD, avg) | B19: =B5/Assumptions!F24 | E19: GDV / total units

Sheet Sensitivity Analysis
A1: MOUNT BREVITOR ESTATE DEVELOPMENT
A2: Sensitivity Analysis | Key Variable Impacts | v2.0
A4: INTEREST RATE SENSITIVITY
A5: Scenario | B5: Interest Rate | C5: Annual Interest (BBD) | D5: 4-Yr Total (BBD) | E5: Impact on Profit (BBD) | F5: Notes
A6: Developer Stated | B6: 0.05 | C6: =80000000*B6 | D6: =C6*3.5 | E6: 0 | F6: Base case per developer
A7: Market Low | B7: 0.06 | C7: =80000000*B7 | D7: =C7*3.5 | E7: =D7-D6 | F7: Bottom of Barbados commercial range
A8: Market Mid | B8: 0.075 | C8: =80000000*B8 | D8: =C8*3.5 | E8: =D8-D6 | F8: Mid-point commercial range
A9: Market High | B9: 0.09 | C9: =80000000*B9 | D9: =C9*3.5 | E9: =D9-D6 | F9: Top of Barbados commercial range
A11: CONSTRUCTION COST SENSITIVITY
A12: Scenario | B12: Cost Adjustment | C12: Total Build Cost (BBD) | D12: Impact vs Base (BBD) | E12: Margin on GDV | F12: Notes
A13: Developer Claimed (-25%) | B13: -0.25 | C13: ='Cost Model'!G16*(1+B13) | D13: =C13-C14 | E13: =('Revenue Model'!G31-('Development Appraisal'!B11-'Cost Model'!G16+C13))/'Revenue Model'!G31 | F13: Unverified proprietary savings
A14: BCQS Base Case (0%) | B14: 0 | C14: ='Cost Model'!G16*(1+B14) | D14: 0 | E14: =('Revenue Model'!G31-('Development Appraisal'!B11-'Cost Model'!G16+C14))/'Revenue Model'!G31 | F14: Independent benchmark
A15: BCQS +10% Escalation | B15: 0.1 | C15: ='Cost Model'!G16*(1+B15) | D15: =C15-C14 | E15: =('Revenue Model'!G31-('Development Appraisal'!B11-'Cost Model'!G16+C15))/'Revenue Model'!G31 | F15: Cost overrun scenario
A16: BCQS +20% Escalation | B16: 0.2 | C16: ='Cost Model'!G16*(1+B16) | D16: =C16-C14 | E16: =('Revenue Model'!G31-('Development Appraisal'!B11-'Cost Model'!G16+C16))/'Revenue Model'!G31 | F16: Severe cost overrun
A18: ABSORPTION RATE SENSITIVITY
A19: Scenario | B19: Units/Year | C19: Sellout (Years) | D19: Additional Fin Cost (BBD) | E19: Impact on Profit | F19: Notes
A20: Conservative | B20: 70 | C20: =355/B20 | D20: =(C20-C21)*80000000*0.05 | E20: =0-D20 | F20: Local demand only
A21: Base Case | B21: 110 | C21: =355/B21 | D21: 0 | E21: =0-D21 | F21: Local + diaspora
A22: Optimistic | B22: 140 | C22: =355/B22 | D22: =(C22-C21)*80000000*0.05 | E22: =0-D22 | F22: All segments strong
A24: PRICING SENSITIVITY
A25: Scenario | B25: Price Change | C25: Revised GDV (BBD) | D25: GDV Change (BBD) | E25: Revised Margin | F25: Notes
A26: Price Cut -10% | B26: -0.1 | C26: ='Revenue Model'!G31*(1+B26) | D26: =C26-C27 | E26: =(C26-'Development Appraisal'!B11)/C26 | F26: Competitive pressure scenario
A27: Base Case (0%) | B27: 0 | C27: ='Revenue Model'!G31*(1+B27) | D27: 0 | E27: =(C27-'Development Appraisal'!B11)/C27 | F27: Current pricing
A28: Price Growth +5% | B28: 0.05 | C28: ='Revenue Model'!G31*(1+B28) | D28: =C28-C27 | E28: =(C28-'Development Appraisal'!B11)/C28 | F28: Northern Barbados growth premium
A29: Price Growth +10% | B29: 0.1 | C29: ='Revenue Model'!G31*(1+B29) | D29: =C29-C27 | E29: =(C29-'Development Appraisal'!B11)/C29 | F29: Strong demand / inflation

Sheet Farm PL
A1: MOUNT BREVITOR ESTATE DEVELOPMENT
A2: Farm / Agri-Estate Profit and Loss | Model C + B | v2.0
A3: Recommended Model: Estate Supply (C) with selective Agri-Tourism (B). See C1 Farm Analysis.
A5: Line Item | B5: Unit | C5: 2025 | D5: 2026 | E5: 2027 | F5: 2028 | G5: Total
A6: FARM REVENUE (BBD)
A7: Aquaponics / Vegetables | B7: BBD | C7: 0 | D7: 200000 | E7: 600000 | F7: 900000 | G7: =SUM(C7:F7)
A8: Dairy / Cheese Production | B8: BBD | C8: 0 | D8: 100000 | E8: 400000 | F8: 700000 | G8: =SUM(C8:F8)
A9: Farm Shop / Direct Sales | B9: BBD | C9: 0 | D9: 100000 | E9: 400000 | F9: 600000 | G9: =SUM(C9:F9)
A10: Restaurant Supply (B2B) | B10: BBD | C10: 0 | D10: 50000 | E10: 300000 | F10: 400000 | G10: =SUM(C10:F10)
A11: Agri-Tourism (tours, events) | B11: BBD | C11: 0 | D11: 50000 | E11: 300000 | F11: 400000 | G11: =SUM(C11:F11)
A12: TOTAL FARM REVENUE | C12: =SUM(C7:C11) | D12: =SUM(D7:D11) | E12: =SUM(E7:E11) | F12: =SUM(F7:F11) | G12: =SUM(G7:G11)
A14: FARM OPERATING COSTS (BBD)
A15: Setup / Capital (containers, equipment) | B15: BBD | C15: 1500000 | D15: 1500000 | E15: 500000 | F15: 0 | G15: =SUM(C15:F15)
A16: Livestock Acquisition | B16: BBD | C16: 0 | D16: 300000 | E16: 100000 | F16: 0 | G16: =SUM(C16:F16)
A17: Feed and Supplies | B17: BBD | C17: 0 | D17: 200000 | E17: 350000 | F17: 400000 | G17: =SUM(C17:F17)
A18: Labour (farm staff) | B18: BBD | C18: 100000 | D18: 400000 | E18: 600000 | F18: 700000 | G18: =SUM(C18:F18)
A19: Utilities (water, power) | B19: BBD | C19: 50000 | D19: 150000 | E19: 200000 | F19: 250000 | G19: =SUM(C19:F19)
A20: Maintenance and Insurance | B20: BBD | C20: 50000 | D20: 100000 | E20: 150000 | F20: 200000 | G20: =SUM(C20:F20)
A21: Marketing and Sales | B21: BBD | C21: 50000 | D21: 100000 | E21: 150000 | F21: 150000 | G21: =SUM(C21:F21)
A22: TOTAL FARM COSTS | C22: =SUM(C15:C21) | D22: =SUM(D15:D21) | E22: =SUM(E15:E21) | F22: =SUM(F15:F21) | G22: =SUM(G15:G21)
A24: FARM NET POSITION
A25: NET FARM PROFIT / (LOSS) | C25: =C12-C22 | D25: =D12-D22 | E25: =E12-E22 | F25: =F12-F22 | G25: =G12-G22
A26: Farm Operating Margin | C26: =IF(C12=0,0,C25/C12) | D26: =IF(D12=0,0,D25/D12) | E26: =IF(E12=0,0,E25/E12) | F26: =IF(F12=0,0,F25/F12) | G26: =IF(G12=0,0,G25/G12)
A28: FLAG: Farm model not confirmed by developer. Revenue projections are advisory estimates based on Model C+B scoring. Capital requirement and revenue ramp require validation against selected operating model.
